Workbook

Sheet README
A1: Phase 3 results sheet
A2: One row per participant, stop, post or choice. Fill in the blue cells only (from row 6). Grey columns are helpers: formulas, do not edit.
A3: Row 4 on each tab is an example of the format. Formulas ignore it.
A4: Participant IDs P01–P20 and the Test B labels are pre-filled. The Test B label says which letter the PERSONALISED plan gets for that person (balanced, fixed seed).
A5: Summary scores every threshold (D2, D18) on STRANGERS ONLY (D43). Test A metrics are split by voice and text (D4). Proportions show Wilson 95% intervals.
A6: Friends and family are a separate launch channel (D43): set Participants → Launch channel. They are reported in their own Summary block.
A8: Tabs
A9: Participants: one row per person (Test A answers and survey).
A10: Swipes and Choices: the 16 swipe reactions and 10 A/B choices (long format, one row per answer).
A11: TestB: preference and fit scores. TestC: plan use, second-plan request and virality counts. Stops: one row per rated stop.
A12: Posts: every recruitment post or B2B contact with minutes spent and sign-ups (D21). TestD: visits and sign-ups by arm (D25, D31).
A13: Discovery: Test E B2B interviews and optional venue conversations (D34).
... A16: Data rules: no audio, no health or allergy details, no nationality. Delete personal data by 31 March 2027 (consent form).

Sheet Summary
A1: Summary — Phase 3 results vs thresholds
A2: All formulas. "no data" until the tabs are filled. Small samples: read a pass as "consistent with", not proof.
A3: z for 95% intervals | B3: 1.96
A5: Metric | B5: Overall | C5: Voice | D5: Text | E5: Threshold | F5: Result | G5: CI low | H5: CI high | I5: Note
A6: Test A — onboarding (strangers only, D43)
A7: Started (consented) | B7: =COUNTIFS(Participants!F6:F205,"Y",Participants!T6:T205,"stranger") -> 0 | C7: =COUNTIFS(Participants!F6:F205,"Y",Participants!T6:T205,"stranger",Participants!H6:H205,"voice") -> 0 | D7: =COUNTIFS(Participants!F6:F205,"Y",Participants!T6:T205,"stranger",Participants!H6:H205,"text") -> 0
A8: Completed the read-back | B8: =COUNTIFS(Participants!F6:F205,"Y",Participants!I6:I205,"Y",Participants!T6:T205,"stranger") -> 0 | C8: =COUNTIFS(Participants!F6:F205,"Y",Participants!I6:I205,"Y",Participants!T6:T205,"stranger",Participants!H6:H205,"voice") -> 0 | D8: =COUNTIFS(Participants!F6:F205,"Y",Participants!I6:I205,"Y",Participants!T6:T205,"stranger",Participants!H6:H205,"text") -> 0
A9: Completion rate | B9: =IF(COUNTIFS(Participants!F6:F205,"Y",Participants!T6:T205,"stranger")=0,"no data",COUNTIFS(Participants!F6:F205,"Y",Participants!I6:I205,"Y",Participants!T6:T205,"stranger")/COUNTIFS(Participants!F6:F205,"Y",Participants!T6:T205,"stranger")) -> no data | C9: =IF(COUNTIFS(Participants!F6:F205,"Y",Participants!T6:T205,"stranger",Participants!H6:H205,"voice")=0,"no data",COUNTIFS(Participants!F6:F205,"Y",Participants!I6:I205,"Y",Participants!T6:T205,"stranger",Participants!H6:H205,"voice")/COUNTIFS(Participants!F6:F205,"Y",Participants!T6:T205,"stranger",Participants!H6:H205,"voice")) -> no data | D9: =IF(COUNTIFS(Participants!F6:F205,"Y",Participants!T6:T205,"stranger",Participants!H6:H205,"text")=0,"no data",COUNTIFS(Participants!F6:F205,"Y",Participants!I6:I205,"Y",Participants!T6:T205,"stranger",Participants!H6:H205,"text")/COUNTIFS(Participants!F6:F205,"Y",Participants!T6:T205,"stranger",Participants!H6:H205,"text")) -> no data | E9: 0.7 | F9: =IF(ISNUMBER(B9),IF(B9>=E9,"PASS","FAIL"),"no data") -> no data | G9: =IF(ISNUMBER(B9),((B9+$B$3^2/(2*COUNTIFS(Participants!F6:F205,"Y",Participants!T6:T205,"stranger")))-$B$3*SQRT(B9*(1-B9)/COUNTIFS(Participants!F6:F205,"Y",Participants!T6:T205,"stranger")+$B$3^2/(4*COUNTIFS(Participants!F6:F205,"Y",Participants!T6:T205,"stranger")^2)))/(1+$B$3^2/COUNTIFS(Participants!F6:F205,"Y",Participants!T6:T205,"stranger")),"") | H9: =IF(ISNUMBER(B9),((B9+$B$3^2/(2*COUNTIFS(Participants!F6:F205,"Y",Participants!T6:T205,"stranger")))+$B$3*SQRT(B9*(1-B9)/COUNTIFS(Participants!F6:F205,"Y",Participants!T6:T205,"stranger")+$B$3^2/(4*COUNTIFS(Participants!F6:F205,"Y",Participants!T6:T205,"stranger")^2)))/(1+$B$3^2/COUNTIFS(Participants!F6:F205,"Y",Participants!T6:T205,"stranger")),"") | I9: Threshold ≥ 70% (D18)
A10: "I felt understood" median (1–5) | B10: =IF(COUNT(Participants!U6:U205)=0,"no data",MEDIAN(Participants!U6:U205)) -> no data | C10: =IF(COUNT(Participants!V6:V205)=0,"no data",MEDIAN(Participants!V6:V205)) -> no data | D10: =IF(COUNT(Participants!W6:W205)=0,"no data",MEDIAN(Participants!W6:W205)) -> no data | E10: 4 | F10: =IF(ISNUMBER(B10),IF(B10>=E10,"PASS","FAIL"),"no data") -> no data | I10: Threshold median ≥ 4 (D18)
A11: "Like a person, not a form" median (1–5) | B11: =IF(COUNT(Participants!X6:X205)=0,"no data",MEDIAN(Participants!X6:X205)) -> no data | C11: =IF(COUNT(Participants!Y6:Y205)=0,"no data",MEDIAN(Participants!Y6:Y205)) -> no data | D11: =IF(COUNT(Participants!Z6:Z205)=0,"no data",MEDIAN(Participants!Z6:Z205)) -> no data | I11: Descriptive
A12: Minutes taken, median | B12: =IF(COUNT(Participants!AA6:AA205)=0,"no data",MEDIAN(Participants!AA6:AA205)) -> no data | C12: =IF(COUNT(Participants!AB6:AB205)=0,"no data",MEDIAN(Participants!AB6:AB205)) -> no data | D12: =IF(COUNT(Participants!AC6:AC205)=0,"no data",MEDIAN(Participants!AC6:AC205)) -> no data | I12: Descriptive
A13: Photos matter, median (1–5) | B13: =IF(COUNT(Participants!AD6:AD205)=0,"no data",MEDIAN(Participants!AD6:AD205)) -> no data | I13: Descriptive (D16)
A14: Shot-card appeal, median (1–5) | B14: =IF(COUNT(Participants!AE6:AE205)=0,"no data",MEDIAN(Participants!AE6:AE205)) -> no data | I14: Descriptive (D16)
A15: Test B — blind comparison (strangers only)
A16: Participants with a preference | B16: =COUNT(TestB!H6:H205) -> 0 | E16: 10 | F16: =IF(B16>=E16,"enough","too few") -> too few | I16: Need ≥ 10 for the 7-of-10 test
A17: Prefer the personalised plan | B17: =SUM(TestB!H6:H205) -> 0 | E17: 7 | F17: =IF(B16<10,"too few",IF(B17>=E17*B16/10,"PASS","FAIL")) -> too few | I17: Threshold ≥ 7 of 10
A18: Share preferring personalised | B18: =IF(COUNT(TestB!H6:H205)=0,"no data",SUM(TestB!H6:H205)/COUNT(TestB!H6:H205)) -> no data | E18: 0.7 | F18: =IF(ISNUMBER(B18),IF(B18>=E18,"PASS","FAIL"),"no data") -> no data | G18: =IF(ISNUMBER(B18),((B18+$B$3^2/(2*COUNT(TestB!H6:H205)))-$B$3*SQRT(B18*(1-B18)/COUNT(TestB!H6:H205)+$B$3^2/(4*COUNT(TestB!H6:H205)^2)))/(1+$B$3^2/COUNT(TestB!H6:H205)),"") | H18: =IF(ISNUMBER(B18),((B18+$B$3^2/(2*COUNT(TestB!H6:H205)))+$B$3*SQRT(B18*(1-B18)/COUNT(TestB!H6:H205)+$B$3^2/(4*COUNT(TestB!H6:H205)^2)))/(1+$B$3^2/COUNT(TestB!H6:H205)),"")
A19: "Fits me" median: personalised | B19: =IF(COUNT(TestB!I6:I205)=0,"no data",MEDIAN(TestB!I6:I205)) -> no data
A20: "Fits me" median: generic | B20: =IF(COUNT(TestB!J6:J205)=0,"no data",MEDIAN(TestB!J6:J205)) -> no data
A21: Test C — real use (strangers only)
A22: Offered a plan | B22: =COUNTIFS(TestC!B6:B205,"<>",TestC!L6:L205,"stranger") -> 0
A23: Used it on a real day (all or part) | B23: =IF(COUNTIFS(TestC!B6:B205,"<>",TestC!L6:L205,"stranger")=0,"no data",(COUNTIFS(TestC!C6:C205,"all",TestC!L6:L205,"stranger")+COUNTIFS(TestC!C6:C205,"part",TestC!L6:L205,"stranger"))/COUNTIFS(TestC!B6:B205,"<>",TestC!L6:L205,"stranger")) -> no data | E23: 0.4 | F23: =IF(ISNUMBER(B23),IF(B23>=E23,"PASS","FAIL"),"no data") -> no data | G23: =IF(ISNUMBER(B23),((B23+$B$3^2/(2*COUNTIFS(TestC!B6:B205,"<>",TestC!L6:L205,"stranger")))-$B$3*SQRT(B23*(1-B23)/COUNTIFS(TestC!B6:B205,"<>",TestC!L6:L205,"stranger")+$B$3^2/(4*COUNTIFS(TestC!B6:B205,"<>",TestC!L6:L205,"stranger")^2)))/(1+$B$3^2/COUNTIFS(TestC!B6:B205,"<>",TestC!L6:L205,"stranger")),"") | H23: =IF(ISNUMBER(B23),((B23+$B$3^2/(2*COUNTIFS(TestC!B6:B205,"<>",TestC!L6:L205,"stranger")))+$B$3*SQRT(B23*(1-B23)/COUNTIFS(TestC!B6:B205,"<>",TestC!L6:L205,"stranger")+$B$3^2/(4*COUNTIFS(TestC!B6:B205,"<>",TestC!L6:L205,"stranger")^2)))/(1+$B$3^2/COUNTIFS(TestC!B6:B205,"<>",TestC!L6:L205,"stranger")),"") | I23: Threshold ≥ 40%
A24: Asked for a second plan within 2 weeks, unprompted | B24: =IF(COUNTIFS(TestC!B6:B205,"<>",TestC!L6:L205,"stranger")=0,"no data",COUNTIFS(TestC!F6:F205,"Y",TestC!L6:L205,"stranger")/COUNTIFS(TestC!B6:B205,"<>",TestC!L6:L205,"stranger")) -> no data | E24: 0.3 | F24: =IF(ISNUMBER(B24),IF(B24>=E24,"PASS","FAIL"),"no data") -> no data | G24: =IF(ISNUMBER(B24),((B24+$B$3^2/(2*COUNTIFS(TestC!B6:B205,"<>",TestC!L6:L205,"stranger")))-$B$3*SQRT(B24*(1-B24)/COUNTIFS(TestC!B6:B205,"<>",TestC!L6:L205,"stranger")+$B$3^2/(4*COUNTIFS(TestC!B6:B205,"<>",TestC!L6:L205,"stranger")^2)))/(1+$B$3^2/COUNTIFS(TestC!B6:B205,"<>",TestC!L6:L205,"stranger")),"") | H24: =IF(ISNUMBER(B24),((B24+$B$3^2/(2*COUNTIFS(TestC!B6:B205,"<>",TestC!L6:L205,"stranger")))+$B$3*SQRT(B24*(1-B24)/COUNTIFS(TestC!B6:B205,"<>",TestC!L6:L205,"stranger")+$B$3^2/(4*COUNTIFS(TestC!B6:B205,"<>",TestC!L6:L205,"stranger")^2)))/(1+$B$3^2/COUNTIFS(TestC!B6:B205,"<>",TestC!L6:L205,"stranger")),"") | I24: Threshold ≥ 30%
A25: Would go again: yes | B25: =IF(COUNTIFS(TestC!E6:E205,"<>",TestC!L6:L205,"stranger")=0,"no data",COUNTIFS(TestC!E6:E205,"yes",TestC!L6:L205,"stranger")/COUNTIFS(TestC!E6:E205,"<>",TestC!L6:L205,"stranger")) -> no data
A26: Stop rating, median (1–5) | B26: =IF(COUNT(Stops!L6:L205)=0,"no data",MEDIAN(Stops!L6:L205)) -> no data
A27: Virality (D23; strangers only, D43)
A28: Invites sent per participant | B28: =IF(COUNTIFS(TestC!B6:B205,"<>",TestC!L6:L205,"stranger")=0,"no data",SUMIFS(TestC!G6:G205,TestC!L6:L205,"stranger")/COUNTIFS(TestC!B6:B205,"<>",TestC!L6:L205,"stranger")) -> no data
A29: Sign-ups per invite | B29: =IF(SUMIFS(TestC!G6:G205,TestC!L6:L205,"stranger")=0,"no data",SUMIFS(TestC!H6:H205,TestC!L6:L205,"stranger")/SUMIFS(TestC!G6:G205,TestC!L6:L205,"stranger")) -> no data
A30: Shot-card shares per participant | B30: =IF(COUNTIFS(TestC!B6:B205,"<>",TestC!L6:L205,"stranger")=0,"no data",SUMIFS(TestC!I6:I205,TestC!L6:L205,"stranger")/COUNTIFS(TestC!B6:B205,"<>",TestC!L6:L205,"stranger")) -> no data
A31: K = invitee sign-ups per participant | B31: =IF(COUNTIFS(TestC!B6:B205,"<>",TestC!L6:L205,"stranger")=0,"no data",SUMIFS(TestC!H6:H205,TestC!L6:L205,"stranger")/COUNTIFS(TestC!B6:B205,"<>",TestC!L6:L205,"stranger")) -> no data | I31: Compare: £50k paths assume K = 0.3; the London expansion gate proposes K ≥ 0.3 (D42)
A32: Friends and family (separate launch channel, D43; descriptive, never scored)
A33: Started | B33: =COUNTIFS(Participants!F6:F205,"Y",Participants!T6:T205,"friends & family") -> 0
A34: Completion rate | B34: =IF(COUNTIFS(Participants!F6:F205,"Y",Participants!T6:T205,"friends & family")=0,"no data",COUNTIFS(Participants!F6:F205,"Y",Participants!I6:I205,"Y",Participants!T6:T205,"friends & family")/COUNTIFS(Participants!F6:F205,"Y",Participants!T6:T205,"friends & family")) -> no data
A35: "I felt understood" median | B35: =IF(COUNT(Participants!AF6:AF205)=0,"no data",MEDIAN(Participants!AF6:AF205)) -> no data
A36: Share preferring personalised | B36: =IF(COUNT(TestB!K6:K205)=0,"no data",SUM(TestB!K6:K205)/COUNT(TestB!K6:K205)) -> no data
A37: K (invitee sign-ups per participant) | B37: =IF(COUNTIFS(TestC!B6:B205,"<>",TestC!L6:L205,"friends & family")=0,"no data",SUMIFS(TestC!H6:H205,TestC!L6:L205,"friends & family")/COUNTIFS(TestC!B6:B205,"<>",TestC!L6:L205,"friends & family")) -> no data
A38: Recruitment (D21)
A39: Sign-ups per post (Tests A–C posts) | B39: =IF(COUNTIF(Posts!B6:B205,"A-C")=0,"no data",SUMIF(Posts!B6:B205,"A-C",Posts!G6:G205)/COUNTIF(Posts!B6:B205,"A-C")) -> no data | I39: Workbook guess: 5
A40: Minutes per post (Tests A–C posts) | B40: =IF(COUNTIF(Posts!B6:B205,"A-C")=0,"no data",SUMIF(Posts!B6:B205,"A-C",Posts!F6:F205)/COUNTIF(Posts!B6:B205,"A-C")) -> no data | I40: Workbook guess: 30
A41: Test E — B2B discovery (proposed read-out: ≥ 2 of 5 on each)
...

Sheet Participants
A1: Participants — Test A
A2: One row per recruited person. Consent = Y means they started.
A3: Example (ignored by formulas) →
A4: P00 | B4: fb-ucl-hiking | C4: A-03 | D4: don't know | E4: 2026-10-19 | F4: Y | G4: N | H4: voice | I4: Y | J4: 26 | L4: 4 | M4: 5 | N4: the swipe list was long | O4: 4 | P4: 3 | Q4: coast | R4: switch off; food | S4: probed crowds twice | T4: stranger | AG4: food, nature
A5: ID | B5: Source group (post link src) | C5: Post ID | D5: How they know Abram | E5: Date started | F5: Consent (Y/N) | G5: Audio 30-day opt-in (Y/N) | H5: First mode | I5: Completed read-back (Y/N) | J5: Minutes taken | K5: Drop-off layer (1–8, blank if completed) | L5: Felt understood (1–5) | M5: Felt like a person (1–5) | N5: Intrusive or tedious (open) | O5: Photos matter (1–5) | P5: Shot-card appeal (1–5) | Q5: Grew up (place type) | R5: Why they travel (up to 2) | S5: Host improvised? (notes) | T5: Launch channel (D43) | U5: understood | stranger | V5: understood | stranger voice | W5: understood | stranger text | X5: person | stranger | Y5: person | stranger voice | Z5: person | stranger text | AA5: minutes | stranger | AB5: minutes | stranger voice | AC5: minutes | stranger text | AD5: photos | stranger | AE5: shot card | stranger | AF5: understood | friends & family | AG5: Inspiring fields (5.7, optional)
A6: P01 | U6: =IF(AND(T6="stranger",ISNUMBER(L6)),L6,"") | V6: =IF(AND(T6="stranger",H6="voice",ISNUMBER(L6)),L6,"") | W6: =IF(AND(T6="stranger",H6="text",ISNUMBER(L6)),L6,"") | X6: =IF(AND(T6="stranger",ISNUMBER(M6)),M6,"") | Y6: =IF(AND(T6="stranger",H6="voice",ISNUMBER(M6)),M6,"") | Z6: =IF(AND(T6="stranger",H6="text",ISNUMBER(M6)),M6,"") | AA6: =IF(AND(T6="stranger",ISNUMBER(J6)),J6,"") | AB6: =IF(AND(T6="stranger",H6="voice",ISNUMBER(J6)),J6,"") | AC6: =IF(AND(T6="stranger",H6="text",ISNUMBER(J6)),J6,"") | AD6: =IF(AND(T6="stranger",ISNUMBER(O6)),O6,"") | AE6: =IF(AND(T6="stranger",ISNUMBER(P6)),P6,"") | AF6: =IF(AND(T6="friends & family",ISNUMBER(L6)),L6,"")
A7: P02 | U7: =IF(AND(T7="stranger",ISNUMBER(L7)),L7,"") | V7: =IF(AND(T7="stranger",H7="voice",ISNUMBER(L7)),L7,"") | W7: =IF(AND(T7="stranger",H7="text",ISNUMBER(L7)),L7,"") | X7: =IF(AND(T7="stranger",ISNUMBER(M7)),M7,"") | Y7: =IF(AND(T7="stranger",H7="voice",ISNUMBER(M7)),M7,"") | Z7: =IF(AND(T7="stranger",H7="text",ISNUMBER(M7)),M7,"") | AA7: =IF(AND(T7="stranger",ISNUMBER(J7)),J7,"") | AB7: =IF(AND(T7="stranger",H7="voice",ISNUMBER(J7)),J7,"") | AC7: =IF(AND(T7="stranger",H7="text",ISNUMBER(J7)),J7,"") | AD7: =IF(AND(T7="stranger",ISNUMBER(O7)),O7,"") | AE7: =IF(AND(T7="stranger",ISNUMBER(P7)),P7,"") | AF7: =IF(AND(T7="friends & family",ISNUMBER(L7)),L7,"")
A8: P03 | U8: =IF(AND(T8="stranger",ISNUMBER(L8)),L8,"") | V8: =IF(AND(T8="stranger",H8="voice",ISNUMBER(L8)),L8,"") | W8: =IF(AND(T8="stranger",H8="text",ISNUMBER(L8)),L8,"") | X8: =IF(AND(T8="stranger",ISNUMBER(M8)),M8,"") | Y8: =IF(AND(T8="stranger",H8="voice",ISNUMBER(M8)),M8,"") | Z8: =IF(AND(T8="stranger",H8="text",ISNUMBER(M8)),M8,"") | AA8: =IF(AND(T8="stranger",ISNUMBER(J8)),J8,"") | AB8: =IF(AND(T8="stranger",H8="voice",ISNUMBER(J8)),J8,"") | AC8: =IF(AND(T8="stranger",H8="text",ISNUMBER(J8)),J8,"") | AD8: =IF(AND(T8="stranger",ISNUMBER(O8)),O8,"") | AE8: =IF(AND(T8="stranger",ISNUMBER(P8)),P8,"") | AF8: =IF(AND(T8="friends & family",ISNUMBER(L8)),L8,"")
A9: P04 | U9: =IF(AND(T9="stranger",ISNUMBER(L9)),L9,"") | V9: =IF(AND(T9="stranger",H9="voice",ISNUMBER(L9)),L9,"") | W9: =IF(AND(T9="stranger",H9="text",ISNUMBER(L9)),L9,"") | X9: =IF(AND(T9="stranger",ISNUMBER(M9)),M9,"") | Y9: =IF(AND(T9="stranger",H9="voice",ISNUMBER(M9)),M9,"") | Z9: =IF(AND(T9="stranger",H9="text",ISNUMBER(M9)),M9,"") | AA9: =IF(AND(T9="stranger",ISNUMBER(J9)),J9,"") | AB9: =IF(AND(T9="stranger",H9="voice",ISNUMBER(J9)),J9,"") | AC9: =IF(AND(T9="stranger",H9="text",ISNUMBER(J9)),J9,"") | AD9: =IF(AND(T9="stranger",ISNUMBER(O9)),O9,"") | AE9: =IF(AND(T9="stranger",ISNUMBER(P9)),P9,"") | AF9: =IF(AND(T9="friends & family",ISNUMBER(L9)),L9,"")
A10: P05 | U10: =IF(AND(T10="stranger",ISNUMBER(L10)),L10,"") | V10: =IF(AND(T10="stranger",H10="voice",ISNUMBER(L10)),L10,"") | W10: =IF(AND(T10="stranger",H10="text",ISNUMBER(L10)),L10,"") | X10: =IF(AND(T10="stranger",ISNUMBER(M10)),M10,"") | Y10: =IF(AND(T10="stranger",H10="voice",ISNUMBER(M10)),M10,"") | Z10: =IF(AND(T10="stranger",H10="text",ISNUMBER(M10)),M10,"") | AA10: =IF(AND(T10="stranger",ISNUMBER(J10)),J10,"") | AB10: =IF(AND(T10="stranger",H10="voice",ISNUMBER(J10)),J10,"") | AC10: =IF(AND(T10="stranger",H10="text",ISNUMBER(J10)),J10,"") | AD10: =IF(AND(T10="stranger",ISNUMBER(O10)),O10,"") | AE10: =IF(AND(T10="stranger",ISNUMBER(P10)),P10,"") | AF10: =IF(AND(T10="friends & family",ISNUMBER(L10)),L10,"")
A11: P06 | U11: =IF(AND(T11="stranger",ISNUMBER(L11)),L11,"") | V11: =IF(AND(T11="stranger",H11="voice",ISNUMBER(L11)),L11,"") | W11: =IF(AND(T11="stranger",H11="text",ISNUMBER(L11)),L11,"") | X11: =IF(AND(T11="stranger",ISNUMBER(M11)),M11,"") | Y11: =IF(AND(T11="stranger",H11="voice",ISNUMBER(M11)),M11,"") | Z11: =IF(AND(T11="stranger",H11="text",ISNUMBER(M11)),M11,"") | AA11: =IF(AND(T11="stranger",ISNUMBER(J11)),J11,"") | AB11: =IF(AND(T11="stranger",H11="voice",ISNUMBER(J11)),J11,"") | AC11: =IF(AND(T11="stranger",H11="text",ISNUMBER(J11)),J11,"") | AD11: =IF(AND(T11="stranger",ISNUMBER(O11)),O11,"") | AE11: =IF(AND(T11="stranger",ISNUMBER(P11)),P11,"") | AF11: =IF(AND(T11="friends & family",ISNUMBER(L11)),L11,"")
A12: P07 | U12: =IF(AND(T12="stranger",ISNUMBER(L12)),L12,"") | V12: =IF(AND(T12="stranger",H12="voice",ISNUMBER(L12)),L12,"") | W12: =IF(AND(T12="stranger",H12="text",ISNUMBER(L12)),L12,"") | X12: =IF(AND(T12="stranger",ISNUMBER(M12)),M12,"") | Y12: =IF(AND(T12="stranger",H12="voice",ISNUMBER(M12)),M12,"") | Z12: =IF(AND(T12="stranger",H12="text",ISNUMBER(M12)),M12,"") | AA12: =IF(AND(T12="stranger",ISNUMBER(J12)),J12,"") | AB12: =IF(AND(T12="stranger",H12="voice",ISNUMBER(J12)),J12,"") | AC12: =IF(AND(T12="stranger",H12="text",ISNUMBER(J12)),J12,"") | AD12: =IF(AND(T12="stranger",ISNUMBER(O12)),O12,"") | AE12: =IF(AND(T12="stranger",ISNUMBER(P12)),P12,"") | AF12: =IF(AND(T12="friends & family",ISNUMBER(L12)),L12,"")
A13: P08 | U13: =IF(AND(T13="stranger",ISNUMBER(L13)),L13,"") | V13: =IF(AND(T13="stranger",H13="voice",ISNUMBER(L13)),L13,"") | W13: =IF(AND(T13="stranger",H13="text",ISNUMBER(L13)),L13,"") | X13: =IF(AND(T13="stranger",ISNUMBER(M13)),M13,"") | Y13: =IF(AND(T13="stranger",H13="voice",ISNUMBER(M13)),M13,"") | Z13: =IF(AND(T13="stranger",H13="text",ISNUMBER(M13)),M13,"") | AA13: =IF(AND(T13="stranger",ISNUMBER(J13)),J13,"") | AB13: =IF(AND(T13="stranger",H13="voice",ISNUMBER(J13)),J13,"") | AC13: =IF(AND(T13="stranger",H13="text",ISNUMBER(J13)),J13,"") | AD13: =IF(AND(T13="stranger",ISNUMBER(O13)),O13,"") | AE13: =IF(AND(T13="stranger",ISNUMBER(P13)),P13,"") | AF13: =IF(AND(T13="friends & family",ISNUMBER(L13)),L13,"")
A14: P09 | U14: =IF(AND(T14="stranger",ISNUMBER(L14)),L14,"") | V14: =IF(AND(T14="stranger",H14="voice",ISNUMBER(L14)),L14,"") | W14: =IF(AND(T14="stranger",H14="text",ISNUMBER(L14)),L14,"") | X14: =IF(AND(T14="stranger",ISNUMBER(M14)),M14,"") | Y14: =IF(AND(T14="stranger",H14="voice",ISNUMBER(M14)),M14,"") | Z14: =IF(AND(T14="stranger",H14="text",ISNUMBER(M14)),M14,"") | AA14: =IF(AND(T14="stranger",ISNUMBER(J14)),J14,"") | AB14: =IF(AND(T14="stranger",H14="voice",ISNUMBER(J14)),J14,"") | AC14: =IF(AND(T14="stranger",H14="text",ISNUMBER(J14)),J14,"") | AD14: =IF(AND(T14="stranger",ISNUMBER(O14)),O14,"") | AE14: =IF(AND(T14="stranger",ISNUMBER(P14)),P14,"") | AF14: =IF(AND(T14="friends & family",ISNUMBER(L14)),L14,"")
A15: P10 | U15: =IF(AND(T15="stranger",ISNUMBER(L15)),L15,"") | V15: =IF(AND(T15="stranger",H15="voice",ISNUMBER(L15)),L15,"") | W15: =IF(AND(T15="stranger",H15="text",ISNUMBER(L15)),L15,"") | X15: =IF(AND(T15="stranger",ISNUMBER(M15)),M15,"") | Y15: =IF(AND(T15="stranger",H15="voice",ISNUMBER(M15)),M15,"") | Z15: =IF(AND(T15="stranger",H15="text",ISNUMBER(M15)),M15,"") | AA15: =IF(AND(T15="stranger",ISNUMBER(J15)),J15,"") | AB15: =IF(AND(T15="stranger",H15="voice",ISNUMBER(J15)),J15,"") | AC15: =IF(AND(T15="stranger",H15="text",ISNUMBER(J15)),J15,"") | AD15: =IF(AND(T15="stranger",ISNUMBER(O15)),O15,"") | AE15: =IF(AND(T15="stranger",ISNUMBER(P15)),P15,"") | AF15: =IF(AND(T15="friends & family",ISNUMBER(L15)),L15,"")
A16: P11 | U16: =IF(AND(T16="stranger",ISNUMBER(L16)),L16,"") | V16: =IF(AND(T16="stranger",H16="voice",ISNUMBER(L16)),L16,"") | W16: =IF(AND(T16="stranger",H16="text",ISNUMBER(L16)),L16,"") | X16: =IF(AND(T16="stranger",ISNUMBER(M16)),M16,"") | Y16: =IF(AND(T16="stranger",H16="voice",ISNUMBER(M16)),M16,"") | Z16: =IF(AND(T16="stranger",H16="text",ISNUMBER(M16)),M16,"") | AA16: =IF(AND(T16="stranger",ISNUMBER(J16)),J16,"") | AB16: =IF(AND(T16="stranger",H16="voice",ISNUMBER(J16)),J16,"") | AC16: =IF(AND(T16="stranger",H16="text",ISNUMBER(J16)),J16,"") | AD16: =IF(AND(T16="stranger",ISNUMBER(O16)),O16,"") | AE16: =IF(AND(T16="stranger",ISNUMBER(P16)),P16,"") | AF16: =IF(AND(T16="friends & family",ISNUMBER(L16)),L16,"")
A17: P12 | U17: =IF(AND(T17="stranger",ISNUMBER(L17)),L17,"") | V17: =IF(AND(T17="stranger",H17="voice",ISNUMBER(L17)),L17,"") | W17: =IF(AND(T17="stranger",H17="text",ISNUMBER(L17)),L17,"") | X17: =IF(AND(T17="stranger",ISNUMBER(M17)),M17,"") | Y17: =IF(AND(T17="stranger",H17="voice",ISNUMBER(M17)),M17,"") | Z17: =IF(AND(T17="stranger",H17="text",ISNUMBER(M17)),M17,"") | AA17: =IF(AND(T17="stranger",ISNUMBER(J17)),J17,"") | AB17: =IF(AND(T17="stranger",H17="voice",ISNUMBER(J17)),J17,"") | AC17: =IF(AND(T17="stranger",H17="text",ISNUMBER(J17)),J17,"") | AD17: =IF(AND(T17="stranger",ISNUMBER(O17)),O17,"") | AE17: =IF(AND(T17="stranger",ISNUMBER(P17)),P17,"") | AF17: =IF(AND(T17="friends & family",ISNUMBER(L17)),L17,"")
... A25: P20 | U25: =IF(AND(T25="stranger",ISNUMBER(L25)),L25,"") | V25: =IF(AND(T25="stranger",H25="voice",ISNUMBER(L25)),L25,"") | W25: =IF(AND(T25="stranger",H25="text",ISNUMBER(L25)),L25,"") | X25: =IF(AND(T25="stranger",ISNUMBER(M25)),M25,"") | Y25: =IF(AND(T25="stranger",H25="voice",ISNUMBER(M25)),M25,"") | Z25: =IF(AND(T25="stranger",H25="text",ISNUMBER(M25)),M25,"") | AA25: =IF(AND(T25="stranger",ISNUMBER(J25)),J25,"") | AB25: =IF(AND(T25="stranger",H25="voice",ISNUMBER(J25)),J25,"") | AC25: =IF(AND(T25="stranger",H25="text",ISNUMBER(J25)),J25,"") | AD25: =IF(AND(T25="stranger",ISNUMBER(O25)),O25,"") | AE25: =IF(AND(T25="stranger",ISNUMBER(P25)),P25,"") | AF25: =IF(AND(T25="friends & family",ISNUMBER(L25)),L25,"")
U26: =IF(AND(T26="stranger",ISNUMBER(L26)),L26,"") | V26: =IF(AND(T26="stranger",H26="voice",ISNUMBER(L26)),L26,"") | W26: =IF(AND(T26="stranger",H26="text",ISNUMBER(L26)),L26,"") | X26: =IF(AND(T26="stranger",ISNUMBER(M26)),M26,"") | Y26: =IF(AND(T26="stranger",H26="voice",ISNUMBER(M26)),M26,"") | Z26: =IF(AND(T26="stranger",H26="text",ISNUMBER(M26)),M26,"") | AA26: =IF(AND(T26="stranger",ISNUMBER(J26)),J26,"") | AB26: =IF(AND(T26="stranger",H26="voice",ISNUMBER(J26)),J26,"") | AC26: =IF(AND(T26="stranger",H26="text",ISNUMBER(J26)),J26,"") | AD26: =IF(AND(T26="stranger",ISNUMBER(O26)),O26,"") | AE26: =IF(AND(T26="stranger",ISNUMBER(P26)),P26,"") | AF26: =IF(AND(T26="friends & family",ISNUMBER(L26)),L26,"")
U27: =IF(AND(T27="stranger",ISNUMBER(L27)),L27,"") | V27: =IF(AND(T27="stranger",H27="voice",ISNUMBER(L27)),L27,"") | W27: =IF(AND(T27="stranger",H27="text",ISNUMBER(L27)),L27,"") | X27: =IF(AND(T27="stranger",ISNUMBER(M27)),M27,"") | Y27: =IF(AND(T27="stranger",H27="voice",ISNUMBER(M27)),M27,"") | Z27: =IF(AND(T27="stranger",H27="text",ISNUMBER(M27)),M27,"") | AA27: =IF(AND(T27="stranger",ISNUMBER(J27)),J27,"") | AB27: =IF(AND(T27="stranger",H27="voice",ISNUMBER(J27)),J27,"") | AC27: =IF(AND(T27="stranger",H27="text",ISNUMBER(J27)),J27,"") | AD27: =IF(AND(T27="stranger",ISNUMBER(O27)),O27,"") | AE27: =IF(AND(T27="stranger",ISNUMBER(P27)),P27,"") | AF27: =IF(AND(T27="friends & family",ISNUMBER(L27)),L27,"")
U28: =IF(AND(T28="stranger",ISNUMBER(L28)),L28,"") | V28: =IF(AND(T28="stranger",H28="voice",ISNUMBER(L28)),L28,"") | W28: =IF(AND(T28="stranger",H28="text",ISNUMBER(L28)),L28,"") | X28: =IF(AND(T28="stranger",ISNUMBER(M28)),M28,"") | Y28: =IF(AND(T28="stranger",H28="voice",ISNUMBER(M28)),M28,"") | Z28: =IF(AND(T28="stranger",H28="text",ISNUMBER(M28)),M28,"") | AA28: =IF(AND(T28="stranger",ISNUMBER(J28)),J28,"") | AB28: =IF(AND(T28="stranger",H28="voice",ISNUMBER(J28)),J28,"") | AC28: =IF(AND(T28="stranger",H28="text",ISNUMBER(J28)),J28,"") | AD28: =IF(AND(T28="stranger",ISNUMBER(O28)),O28,"") | AE28: =IF(AND(T28="stranger",ISNUMBER(P28)),P28,"") | AF28: =IF(AND(T28="friends & family",ISNUMBER(L28)),L28,"")
U29: =IF(AND(T29="stranger",ISNUMBER(L29)),L29,"") | V29: =IF(AND(T29="stranger",H29="voice",ISNUMBER(L29)),L29,"") | W29: =IF(AND(T29="stranger",H29="text",ISNUMBER(L29)),L29,"") | X29: =IF(AND(T29="stranger",ISNUMBER(M29)),M29,"") | Y29: =IF(AND(T29="stranger",H29="voice",ISNUMBER(M29)),M29,"") | Z29: =IF(AND(T29="stranger",H29="text",ISNUMBER(M29)),M29,"") | AA29: =IF(AND(T29="stranger",ISNUMBER(J29)),J29,"") | AB29: =IF(AND(T29="stranger",H29="voice",ISNUMBER(J29)),J29,"") | AC29: =IF(AND(T29="stranger",H29="text",ISNUMBER(J29)),J29,"") | AD29: =IF(AND(T29="stranger",ISNUMBER(O29)),O29,"") | AE29: =IF(AND(T29="stranger",ISNUMBER(P29)),P29,"") | AF29: =IF(AND(T29="friends & family",ISNUMBER(L29)),L29,"")
U30: =IF(AND(T30="stranger",ISNUMBER(L30)),L30,"") | V30: =IF(AND(T30="stranger",H30="voice",ISNUMBER(L30)),L30,"") | W30: =IF(AND(T30="stranger",H30="text",ISNUMBER(L30)),L30,"") | X30: =IF(AND(T30="stranger",ISNUMBER(M30)),M30,"") | Y30: =IF(AND(T30="stranger",H30="voice",ISNUMBER(M30)),M30,"") | Z30: =IF(AND(T30="stranger",H30="text",ISNUMBER(M30)),M30,"") | AA30: =IF(AND(T30="stranger",ISNUMBER(J30)),J30,"") | AB30: =IF(AND(T30="stranger",H30="voice",ISNUMBER(J30)),J30,"") | AC30: =IF(AND(T30="stranger",H30="text",ISNUMBER(J30)),J30,"") | AD30: =IF(AND(T30="stranger",ISNUMBER(O30)),O30,"") | AE30: =IF(AND(T30="stranger",ISNUMBER(P30)),P30,"") | AF30: =IF(AND(T30="friends & family",ISNUMBER(L30)),L30,"")
U31: =IF(AND(T31="stranger",ISNUMBER(L31)),L31,"") | V31: =IF(AND(T31="stranger",H31="voice",ISNUMBER(L31)),L31,"") | W31: =IF(AND(T31="stranger",H31="text",ISNUMBER(L31)),L31,"") | X31: =IF(AND(T31="stranger",ISNUMBER(M31)),M31,"") | Y31: =IF(AND(T31="stranger",H31="voice",ISNUMBER(M31)),M31,"") | Z31: =IF(AND(T31="stranger",H31="text",ISNUMBER(M31)),M31,"") | AA31: =IF(AND(T31="stranger",ISNUMBER(J31)),J31,"") | AB31: =IF(AND(T31="stranger",H31="voice",ISNUMBER(J31)),J31,"") | AC31: =IF(AND(T31="stranger",H31="text",ISNUMBER(J31)),J31,"") | AD31: =IF(AND(T31="stranger",ISNUMBER(O31)),O31,"") | AE31: =IF(AND(T31="stranger",ISNUMBER(P31)),P31,"") | AF31: =IF(AND(T31="friends & family",ISNUMBER(L31)),L31,"")
U32: =IF(AND(T32="stranger",ISNUMBER(L32)),L32,"") | V32: =IF(AND(T32="stranger",H32="voice",ISNUMBER(L32)),L32,"") | W32: =IF(AND(T32="stranger",H32="text",ISNUMBER(L32)),L32,"") | X32: =IF(AND(T32="stranger",ISNUMBER(M32)),M32,"") | Y32: =IF(AND(T32="stranger",H32="voice",ISNUMBER(M32)),M32,"") | Z32: =IF(AND(T32="stranger",H32="text",ISNUMBER(M32)),M32,"") | AA32: =IF(AND(T32="stranger",ISNUMBER(J32)),J32,"") | AB32: =IF(AND(T32="stranger",H32="voice",ISNUMBER(J32)),J32,"") | AC32: =IF(AND(T32="stranger",H32="text",ISNUMBER(J32)),J32,"") | AD32: =IF(AND(T32="stranger",ISNUMBER(O32)),O32,"") | AE32: =IF(AND(T32="stranger",ISNUMBER(P32)),P32,"") | AF32: =IF(AND(T32="friends & family",ISNUMBER(L32)),L32,"")
U33: =IF(AND(T33="stranger",ISNUMBER(L33)),L33,"") | V33: =IF(AND(T33="stranger",H33="voice",ISNUMBER(L33)),L33,"") | W33: =IF(AND(T33="stranger",H33="text",ISNUMBER(L33)),L33,"") | X33: =IF(AND(T33="stranger",ISNUMBER(M33)),M33,"") | Y33: =IF(AND(T33="stranger",H33="voice",ISNUMBER(M33)),M33,"") | Z33: =IF(AND(T33="stranger",H33="text",ISNUMBER(M33)),M33,"") | AA33: =IF(AND(T33="stranger",ISNUMBER(J33)),J33,"") | AB33: =IF(AND(T33="stranger",H33="voice",ISNUMBER(J33)),J33,"") | AC33: =IF(AND(T33="stranger",H33="text",ISNUMBER(J33)),J33,"") | AD33: =IF(AND(T33="stranger",ISNUMBER(O33)),O33,"") | AE33: =IF(AND(T33="stranger",ISNUMBER(P33)),P33,"") | AF33: =IF(AND(T33="friends & family",ISNUMBER(L33)),L33,"")
U34: =IF(AND(T34="stranger",ISNUMBER(L34)),L34,"") | V34: =IF(AND(T34="stranger",H34="voice",ISNUMBER(L34)),L34,"") | W34: =IF(AND(T34="stranger",H34="text",ISNUMBER(L34)),L34,"") | X34: =IF(AND(T34="stranger",ISNUMBER(M34)),M34,"") | Y34: =IF(AND(T34="stranger",H34="voice",ISNUMBER(M34)),M34,"") | Z34: =IF(AND(T34="stranger",H34="text",ISNUMBER(M34)),M34,"") | AA34: =IF(AND(T34="stranger",ISNUMBER(J34)),J34,"") | AB34: =IF(AND(T34="stranger",H34="voice",ISNUMBER(J34)),J34,"") | AC34: =IF(AND(T34="stranger",H34="text",ISNUMBER(J34)),J34,"") | AD34: =IF(AND(T34="stranger",ISNUMBER(O34)),O34,"") | AE34: =IF(AND(T34="stranger",ISNUMBER(P34)),P34,"") | AF34: =IF(AND(T34="friends & family",ISNUMBER(L34)),L34,"")
U35: =IF(AND(T35="stranger",ISNUMBER(L35)),L35,"") | V35: =IF(AND(T35="stranger",H35="voice",ISNUMBER(L35)),L35,"") | W35: =IF(AND(T35="stranger",H35="text",ISNUMBER(L35)),L35,"") | X35: =IF(AND(T35="stranger",ISNUMBER(M35)),M35,"") | Y35: =IF(AND(T35="stranger",H35="voice",ISNUMBER(M35)),M35,"") | Z35: =IF(AND(T35="stranger",H35="text",ISNUMBER(M35)),M35,"") | AA35: =IF(AND(T35="stranger",ISNUMBER(J35)),J35,"") | AB35: =IF(AND(T35="stranger",H35="voice",ISNUMBER(J35)),J35,"") | AC35: =IF(AND(T35="stranger",H35="text",ISNUMBER(J35)),J35,"") | AD35: =IF(AND(T35="stranger",ISNUMBER(O35)),O35,"") | AE35: =IF(AND(T35="stranger",ISNUMBER(P35)),P35,"") | AF35: =IF(AND(T35="friends & family",ISNUMBER(L35)),L35,"")
U36: =IF(AND(T36="stranger",ISNUMBER(L36)),L36,"") | V36: =IF(AND(T36="stranger",H36="voice",ISNUMBER(L36)),L36,"") | W36: =IF(AND(T36="stranger",H36="text",ISNUMBER(L36)),L36,"") | X36: =IF(AND(T36="stranger",ISNUMBER(M36)),M36,"") | Y36: =IF(AND(T36="stranger",H36="voice",ISNUMBER(M36)),M36,"") | Z36: =IF(AND(T36="stranger",H36="text",ISNUMBER(M36)),M36,"") | AA36: =IF(AND(T36="stranger",ISNUMBER(J36)),J36,"") | AB36: =IF(AND(T36="stranger",H36="voice",ISNUMBER(J36)),J36,"") | AC36: =IF(AND(T36="stranger",H36="text",ISNUMBER(J36)),J36,"") | AD36: =IF(AND(T36="stranger",ISNUMBER(O36)),O36,"") | AE36: =IF(AND(T36="stranger",ISNUMBER(P36)),P36,"") | AF36: =IF(AND(T36="friends & family",ISNUMBER(L36)),L36,"")
U37: =IF(AND(T37="stranger",ISNUMBER(L37)),L37,"") | V37: =IF(AND(T37="stranger",H37="voice",ISNUMBER(L37)),L37,"") | W37: =IF(AND(T37="stranger",H37="text",ISNUMBER(L37)),L37,"") | X37: =IF(AND(T37="stranger",ISNUMBER(M37)),M37,"") | Y37: =IF(AND(T37="stranger",H37="voice",ISNUMBER(M37)),M37,"") | Z37: =IF(AND(T37="stranger",H37="text",ISNUMBER(M37)),M37,"") | AA37: =IF(AND(T37="stranger",ISNUMBER(J37)),J37,"") | AB37: =IF(AND(T37="stranger",H37="voice",ISNUMBER(J37)),J37,"") | AC37: =IF(AND(T37="stranger",H37="text",ISNUMBER(J37)),J37,"") | AD37: =IF(AND(T37="stranger",ISNUMBER(O37)),O37,"") | AE37: =IF(AND(T37="stranger",ISNUMBER(P37)),P37,"") | AF37: =IF(AND(T37="friends & family",ISNUMBER(L37)),L37,"")
... U205: =IF(AND(T205="stranger",ISNUMBER(L205)),L205,"") | V205: =IF(AND(T205="stranger",H205="voice",ISNUMBER(L205)),L205,"") | W205: =IF(AND(T205="stranger",H205="text",ISNUMBER(L205)),L205,"") | X205: =IF(AND(T205="stranger",ISNUMBER(M205)),M205,"") | Y205: =IF(AND(T205="stranger",H205="voice",ISNUMBER(M205)),M205,"") | Z205: =IF(AND(T205="stranger",H205="text",ISNUMBER(M205)),M205,"") | AA205: =IF(AND(T205="stranger",ISNUMBER(J205)),J205,"") | AB205: =IF(AND(T205="stranger",H205="voice",ISNUMBER(J205)),J205,"") | AC205: =IF(AND(T205="stranger",H205="text",ISNUMBER(J205)),J205,"") | AD205: =IF(AND(T205="stranger",ISNUMBER(O205)),O205,"") | AE205: =IF(AND(T205="stranger",ISNUMBER(P205)),P205,"") | AF205: =IF(AND(T205="friends & family",ISNUMBER(L205)),L205,"")

Sheet Swipes
A1: Swipes — 16 London items
A2: Reaction: 1 Loved it · 2 It was fine · 3 Didn't enjoy it · 4 Haven't been.
A3: Example (ignored by formulas) →
A4: P00 | B4: 2 | C4: Uber Boat on the Thames | D4: 1 | E4: the wind and the views
A5: Participant | B5: Item # | C5: Item | D5: Reaction (1–4) | E5: Follow-up answer

Sheet Choices
A1: This or that — 10 tasks
A2: Tasks and plans are in validation/conjoint/design.csv.
A3: Example (ignored by formulas) →
A4: P00 | B4: 1 | C4: B
A5: Participant | B5: Task (1–10) | C5: Chose (A/B)

Sheet TestB
A1: Test B — blind plan comparison
A2: Column B is pre-randomised: the letter the PERSONALISED plan gets. Never tell the participant.
A3: Example (ignored by formulas) →
A4: P00 | B4: B | C4: B | D4: 3 | E4: 5 | F4: more boat, less queueing
A5: Participant | B5: Personalised plan label | C5: Preferred (A/B) | D5: "Fits me" plan A (1–5) | E5: "Fits me" plan B (1–5) | F5: Why (open) | G5: channel | H5: prefers personalised | stranger | I5: fit | personalised | stranger | J5: fit | generic | stranger | K5: prefers personalised | friends & family
A6: P01 | B6: A | G6: =IFERROR(INDEX(Participants!$T$6:$T$205,MATCH(A6,Participants!$A$6:$A$205,0)),"") -> 0 | H6: =IF(OR(C6="",G6<>"stranger"),"",IF(C6=B6,1,0)) | I6: =IF(G6<>"stranger","",IF(B6="A",IF(ISNUMBER(D6),D6,""),IF(B6="B",IF(ISNUMBER(E6),E6,""),""))) | J6: =IF(G6<>"stranger","",IF(B6="A",IF(ISNUMBER(E6),E6,""),IF(B6="B",IF(ISNUMBER(D6),D6,""),""))) | K6: =IF(OR(C6="",G6<>"friends & family"),"",IF(C6=B6,1,0))
A7: P02 | B7: A | G7: =IFERROR(INDEX(Participants!$T$6:$T$205,MATCH(A7,Participants!$A$6:$A$205,0)),"") -> 0 | H7: =IF(OR(C7="",G7<>"stranger"),"",IF(C7=B7,1,0)) | I7: =IF(G7<>"stranger","",IF(B7="A",IF(ISNUMBER(D7),D7,""),IF(B7="B",IF(ISNUMBER(E7),E7,""),""))) | J7: =IF(G7<>"stranger","",IF(B7="A",IF(ISNUMBER(E7),E7,""),IF(B7="B",IF(ISNUMBER(D7),D7,""),""))) | K7: =IF(OR(C7="",G7<>"friends & family"),"",IF(C7=B7,1,0))
A8: P03 | B8: B | G8: =IFERROR(INDEX(Participants!$T$6:$T$205,MATCH(A8,Participants!$A$6:$A$205,0)),"") -> 0 | H8: =IF(OR(C8="",G8<>"stranger"),"",IF(C8=B8,1,0)) | I8: =IF(G8<>"stranger","",IF(B8="A",IF(ISNUMBER(D8),D8,""),IF(B8="B",IF(ISNUMBER(E8),E8,""),""))) | J8: =IF(G8<>"stranger","",IF(B8="A",IF(ISNUMBER(E8),E8,""),IF(B8="B",IF(ISNUMBER(D8),D8,""),""))) | K8: =IF(OR(C8="",G8<>"friends & family"),"",IF(C8=B8,1,0))
A9: P04 | B9: B | G9: =IFERROR(INDEX(Participants!$T$6:$T$205,MATCH(A9,Participants!$A$6:$A$205,0)),"") -> 0 | H9: =IF(OR(C9="",G9<>"stranger"),"",IF(C9=B9,1,0)) | I9: =IF(G9<>"stranger","",IF(B9="A",IF(ISNUMBER(D9),D9,""),IF(B9="B",IF(ISNUMBER(E9),E9,""),""))) | J9: =IF(G9<>"stranger","",IF(B9="A",IF(ISNUMBER(E9),E9,""),IF(B9="B",IF(ISNUMBER(D9),D9,""),""))) | K9: =IF(OR(C9="",G9<>"friends & family"),"",IF(C9=B9,1,0))
A10: P05 | B10: B | G10: =IFERROR(INDEX(Participants!$T$6:$T$205,MATCH(A10,Participants!$A$6:$A$205,0)),"") -> 0 | H10: =IF(OR(C10="",G10<>"stranger"),"",IF(C10=B10,1,0)) | I10: =IF(G10<>"stranger","",IF(B10="A",IF(ISNUMBER(D10),D10,""),IF(B10="B",IF(ISNUMBER(E10),E10,""),""))) | J10: =IF(G10<>"stranger","",IF(B10="A",IF(ISNUMBER(E10),E10,""),IF(B10="B",IF(ISNUMBER(D10),D10,""),""))) | K10: =IF(OR(C10="",G10<>"friends & family"),"",IF(C10=B10,1,0))
A11: P06 | B11: B | G11: =IFERROR(INDEX(Participants!$T$6:$T$205,MATCH(A11,Participants!$A$6:$A$205,0)),"") -> 0 | H11: =IF(OR(C11="",G11<>"stranger"),"",IF(C11=B11,1,0)) | I11: =IF(G11<>"stranger","",IF(B11="A",IF(ISNUMBER(D11),D11,""),IF(B11="B",IF(ISNUMBER(E11),E11,""),""))) | J11: =IF(G11<>"stranger","",IF(B11="A",IF(ISNUMBER(E11),E11,""),IF(B11="B",IF(ISNUMBER(D11),D11,""),""))) | K11: =IF(OR(C11="",G11<>"friends & family"),"",IF(C11=B11,1,0))
A12: P07 | B12: A | G12: =IFERROR(INDEX(Participants!$T$6:$T$205,MATCH(A12,Participants!$A$6:$A$205,0)),"") -> 0 | H12: =IF(OR(C12="",G12<>"stranger"),"",IF(C12=B12,1,0)) | I12: =IF(G12<>"stranger","",IF(B12="A",IF(ISNUMBER(D12),D12,""),IF(B12="B",IF(ISNUMBER(E12),E12,""),""))) | J12: =IF(G12<>"stranger","",IF(B12="A",IF(ISNUMBER(E12),E12,""),IF(B12="B",IF(ISNUMBER(D12),D12,""),""))) | K12: =IF(OR(C12="",G12<>"friends & family"),"",IF(C12=B12,1,0))
A13: P08 | B13: B | G13: =IFERROR(INDEX(Participants!$T$6:$T$205,MATCH(A13,Participants!$A$6:$A$205,0)),"") -> 0 | H13: =IF(OR(C13="",G13<>"stranger"),"",IF(C13=B13,1,0)) | I13: =IF(G13<>"stranger","",IF(B13="A",IF(ISNUMBER(D13),D13,""),IF(B13="B",IF(ISNUMBER(E13),E13,""),""))) | J13: =IF(G13<>"stranger","",IF(B13="A",IF(ISNUMBER(E13),E13,""),IF(B13="B",IF(ISNUMBER(D13),D13,""),""))) | K13: =IF(OR(C13="",G13<>"friends & family"),"",IF(C13=B13,1,0))
A14: P09 | B14: A | G14: =IFERROR(INDEX(Participants!$T$6:$T$205,MATCH(A14,Participants!$A$6:$A$205,0)),"") -> 0 | H14: =IF(OR(C14="",G14<>"stranger"),"",IF(C14=B14,1,0)) | I14: =IF(G14<>"stranger","",IF(B14="A",IF(ISNUMBER(D14),D14,""),IF(B14="B",IF(ISNUMBER(E14),E14,""),""))) | J14: =IF(G14<>"stranger","",IF(B14="A",IF(ISNUMBER(E14),E14,""),IF(B14="B",IF(ISNUMBER(D14),D14,""),""))) | K14: =IF(OR(C14="",G14<>"friends & family"),"",IF(C14=B14,1,0))
A15: P10 | B15: A | G15: =IFERROR(INDEX(Participants!$T$6:$T$205,MATCH(A15,Participants!$A$6:$A$205,0)),"") -> 0 | H15: =IF(OR(C15="",G15<>"stranger"),"",IF(C15=B15,1,0)) | I15: =IF(G15<>"stranger","",IF(B15="A",IF(ISNUMBER(D15),D15,""),IF(B15="B",IF(ISNUMBER(E15),E15,""),""))) | J15: =IF(G15<>"stranger","",IF(B15="A",IF(ISNUMBER(E15),E15,""),IF(B15="B",IF(ISNUMBER(D15),D15,""),""))) | K15: =IF(OR(C15="",G15<>"friends & family"),"",IF(C15=B15,1,0))
A16: P11 | B16: A | G16: =IFERROR(INDEX(Participants!$T$6:$T$205,MATCH(A16,Participants!$A$6:$A$205,0)),"") -> 0 | H16: =IF(OR(C16="",G16<>"stranger"),"",IF(C16=B16,1,0)) | I16: =IF(G16<>"stranger","",IF(B16="A",IF(ISNUMBER(D16),D16,""),IF(B16="B",IF(ISNUMBER(E16),E16,""),""))) | J16: =IF(G16<>"stranger","",IF(B16="A",IF(ISNUMBER(E16),E16,""),IF(B16="B",IF(ISNUMBER(D16),D16,""),""))) | K16: =IF(OR(C16="",G16<>"friends & family"),"",IF(C16=B16,1,0))
A17: P12 | B17: B | G17: =IFERROR(INDEX(Participants!$T$6:$T$205,MATCH(A17,Participants!$A$6:$A$205,0)),"") -> 0 | H17: =IF(OR(C17="",G17<>"stranger"),"",IF(C17=B17,1,0)) | I17: =IF(G17<>"stranger","",IF(B17="A",IF(ISNUMBER(D17),D17,""),IF(B17="B",IF(ISNUMBER(E17),E17,""),""))) | J17: =IF(G17<>"stranger","",IF(B17="A",IF(ISNUMBER(E17),E17,""),IF(B17="B",IF(ISNUMBER(D17),D17,""),""))) | K17: =IF(OR(C17="",G17<>"friends & family"),"",IF(C17=B17,1,0))
... A25: P20 | B25: B | G25: =IFERROR(INDEX(Participants!$T$6:$T$205,MATCH(A25,Participants!$A$6:$A$205,0)),"") -> 0 | H25: =IF(OR(C25="",G25<>"stranger"),"",IF(C25=B25,1,0)) | I25: =IF(G25<>"stranger","",IF(B25="A",IF(ISNUMBER(D25),D25,""),IF(B25="B",IF(ISNUMBER(E25),E25,""),""))) | J25: =IF(G25<>"stranger","",IF(B25="A",IF(ISNUMBER(E25),E25,""),IF(B25="B",IF(ISNUMBER(D25),D25,""),""))) | K25: =IF(OR(C25="",G25<>"friends & family"),"",IF(C25=B25,1,0))
G26: =IFERROR(INDEX(Participants!$T$6:$T$205,MATCH(A26,Participants!$A$6:$A$205,0)),"") | H26: =IF(OR(C26="",G26<>"stranger"),"",IF(C26=B26,1,0)) | I26: =IF(G26<>"stranger","",IF(B26="A",IF(ISNUMBER(D26),D26,""),IF(B26="B",IF(ISNUMBER(E26),E26,""),""))) | J26: =IF(G26<>"stranger","",IF(B26="A",IF(ISNUMBER(E26),E26,""),IF(B26="B",IF(ISNUMBER(D26),D26,""),""))) | K26: =IF(OR(C26="",G26<>"friends & family"),"",IF(C26=B26,1,0))
G27: =IFERROR(INDEX(Participants!$T$6:$T$205,MATCH(A27,Participants!$A$6:$A$205,0)),"") | H27: =IF(OR(C27="",G27<>"stranger"),"",IF(C27=B27,1,0)) | I27: =IF(G27<>"stranger","",IF(B27="A",IF(ISNUMBER(D27),D27,""),IF(B27="B",IF(ISNUMBER(E27),E27,""),""))) | J27: =IF(G27<>"stranger","",IF(B27="A",IF(ISNUMBER(E27),E27,""),IF(B27="B",IF(ISNUMBER(D27),D27,""),""))) | K27: =IF(OR(C27="",G27<>"friends & family"),"",IF(C27=B27,1,0))
G28: =IFERROR(INDEX(Participants!$T$6:$T$205,MATCH(A28,Participants!$A$6:$A$205,0)),"") | H28: =IF(OR(C28="",G28<>"stranger"),"",IF(C28=B28,1,0)) | I28: =IF(G28<>"stranger","",IF(B28="A",IF(ISNUMBER(D28),D28,""),IF(B28="B",IF(ISNUMBER(E28),E28,""),""))) | J28: =IF(G28<>"stranger","",IF(B28="A",IF(ISNUMBER(E28),E28,""),IF(B28="B",IF(ISNUMBER(D28),D28,""),""))) | K28: =IF(OR(C28="",G28<>"friends & family"),"",IF(C28=B28,1,0))
G29: =IFERROR(INDEX(Participants!$T$6:$T$205,MATCH(A29,Participants!$A$6:$A$205,0)),"") | H29: =IF(OR(C29="",G29<>"stranger"),"",IF(C29=B29,1,0)) | I29: =IF(G29<>"stranger","",IF(B29="A",IF(ISNUMBER(D29),D29,""),IF(B29="B",IF(ISNUMBER(E29),E29,""),""))) | J29: =IF(G29<>"stranger","",IF(B29="A",IF(ISNUMBER(E29),E29,""),IF(B29="B",IF(ISNUMBER(D29),D29,""),""))) | K29: =IF(OR(C29="",G29<>"friends & family"),"",IF(C29=B29,1,0))
G30: =IFERROR(INDEX(Participants!$T$6:$T$205,MATCH(A30,Participants!$A$6:$A$205,0)),"") | H30: =IF(OR(C30="",G30<>"stranger"),"",IF(C30=B30,1,0)) | I30: =IF(G30<>"stranger","",IF(B30="A",IF(ISNUMBER(D30),D30,""),IF(B30="B",IF(ISNUMBER(E30),E30,""),""))) | J30: =IF(G30<>"stranger","",IF(B30="A",IF(ISNUMBER(E30),E30,""),IF(B30="B",IF(ISNUMBER(D30),D30,""),""))) | K30: =IF(OR(C30="",G30<>"friends & family"),"",IF(C30=B30,1,0))
G31: =IFERROR(INDEX(Participants!$T$6:$T$205,MATCH(A31,Participants!$A$6:$A$205,0)),"") | H31: =IF(OR(C31="",G31<>"stranger"),"",IF(C31=B31,1,0)) | I31: =IF(G31<>"stranger","",IF(B31="A",IF(ISNUMBER(D31),D31,""),IF(B31="B",IF(ISNUMBER(E31),E31,""),""))) | J31: =IF(G31<>"stranger","",IF(B31="A",IF(ISNUMBER(E31),E31,""),IF(B31="B",IF(ISNUMBER(D31),D31,""),""))) | K31: =IF(OR(C31="",G31<>"friends & family"),"",IF(C31=B31,1,0))
G32: =IFERROR(INDEX(Participants!$T$6:$T$205,MATCH(A32,Participants!$A$6:$A$205,0)),"") | H32: =IF(OR(C32="",G32<>"stranger"),"",IF(C32=B32,1,0)) | I32: =IF(G32<>"stranger","",IF(B32="A",IF(ISNUMBER(D32),D32,""),IF(B32="B",IF(ISNUMBER(E32),E32,""),""))) | J32: =IF(G32<>"stranger","",IF(B32="A",IF(ISNUMBER(E32),E32,""),IF(B32="B",IF(ISNUMBER(D32),D32,""),""))) | K32: =IF(OR(C32="",G32<>"friends & family"),"",IF(C32=B32,1,0))
G33: =IFERROR(INDEX(Participants!$T$6:$T$205,MATCH(A33,Participants!$A$6:$A$205,0)),"") | H33: =IF(OR(C33="",G33<>"stranger"),"",IF(C33=B33,1,0)) | I33: =IF(G33<>"stranger","",IF(B33="A",IF(ISNUMBER(D33),D33,""),IF(B33="B",IF(ISNUMBER(E33),E33,""),""))) | J33: =IF(G33<>"stranger","",IF(B33="A",IF(ISNUMBER(E33),E33,""),IF(B33="B",IF(ISNUMBER(D33),D33,""),""))) | K33: =IF(OR(C33="",G33<>"friends & family"),"",IF(C33=B33,1,0))
G34: =IFERROR(INDEX(Participants!$T$6:$T$205,MATCH(A34,Participants!$A$6:$A$205,0)),"") | H34: =IF(OR(C34="",G34<>"stranger"),"",IF(C34=B34,1,0)) | I34: =IF(G34<>"stranger","",IF(B34="A",IF(ISNUMBER(D34),D34,""),IF(B34="B",IF(ISNUMBER(E34),E34,""),""))) | J34: =IF(G34<>"stranger","",IF(B34="A",IF(ISNUMBER(E34),E34,""),IF(B34="B",IF(ISNUMBER(D34),D34,""),""))) | K34: =IF(OR(C34="",G34<>"friends & family"),"",IF(C34=B34,1,0))
G35: =IFERROR(INDEX(Participants!$T$6:$T$205,MATCH(A35,Participants!$A$6:$A$205,0)),"") | H35: =IF(OR(C35="",G35<>"stranger"),"",IF(C35=B35,1,0)) | I35: =IF(G35<>"stranger","",IF(B35="A",IF(ISNUMBER(D35),D35,""),IF(B35="B",IF(ISNUMBER(E35),E35,""),""))) | J35: =IF(G35<>"stranger","",IF(B35="A",IF(ISNUMBER(E35),E35,""),IF(B35="B",IF(ISNUMBER(D35),D35,""),""))) | K35: =IF(OR(C35="",G35<>"friends & family"),"",IF(C35=B35,1,0))
G36: =IFERROR(INDEX(Participants!$T$6:$T$205,MATCH(A36,Participants!$A$6:$A$205,0)),"") | H36: =IF(OR(C36="",G36<>"stranger"),"",IF(C36=B36,1,0)) | I36: =IF(G36<>"stranger","",IF(B36="A",IF(ISNUMBER(D36),D36,""),IF(B36="B",IF(ISNUMBER(E36),E36,""),""))) | J36: =IF(G36<>"stranger","",IF(B36="A",IF(ISNUMBER(E36),E36,""),IF(B36="B",IF(ISNUMBER(D36),D36,""),""))) | K36: =IF(OR(C36="",G36<>"friends & family"),"",IF(C36=B36,1,0))
G37: =IFERROR(INDEX(Participants!$T$6:$T$205,MATCH(A37,Participants!$A$6:$A$205,0)),"") | H37: =IF(OR(C37="",G37<>"stranger"),"",IF(C37=B37,1,0)) | I37: =IF(G37<>"stranger","",IF(B37="A",IF(ISNUMBER(D37),D37,""),IF(B37="B",IF(ISNUMBER(E37),E37,""),""))) | J37: =IF(G37<>"stranger","",IF(B37="A",IF(ISNUMBER(E37),E37,""),IF(B37="B",IF(ISNUMBER(D37),D37,""),""))) | K37: =IF(OR(C37="",G37<>"friends & family"),"",IF(C37=B37,1,0))
... G205: =IFERROR(INDEX(Participants!$T$6:$T$205,MATCH(A205,Participants!$A$6:$A$205,0)),"") | H205: =IF(OR(C205="",G205<>"stranger"),"",IF(C205=B205,1,0)) | I205: =IF(G205<>"stranger","",IF(B205="A",IF(ISNUMBER(D205),D205,""),IF(B205="B",IF(ISNUMBER(E205),E205,""),""))) | J205: =IF(G205<>"stranger","",IF(B205="A",IF(ISNUMBER(E205),E205,""),IF(B205="B",IF(ISNUMBER(D205),D205,""),""))) | K205: =IF(OR(C205="",G205<>"friends & family"),"",IF(C205=B205,1,0))

Sheet TestC
A1: Test C — real day, second plan, virality (D23)
A2: One row per participant offered a plan. Counts are whole numbers (0 if none).
A3: Example (ignored by formulas) →
A4: P00 | B4: personalised | C4: part | D4: 2026-10-25 | E4: yes | F4: N | G4: 2 | H4: 1 | I4: 1 | J4: Y | K4: calm, the boat was the best bit
A5: Participant | B5: Plan offered | C5: Used it | D5: Date of the day | E5: Would go again | F5: Asked for 2nd plan within 14 days, unprompted (Y/N) | G5: Invites sent | H5: Invitee sign-ups (ref code or named) | I5: Shot-card shares | J5: Brought a friend on the day (Y/N) | K5: How it felt (open) | L5: channel
A6: P01 | L6: =IFERROR(INDEX(Participants!$T$6:$T$205,MATCH(A6,Participants!$A$6:$A$205,0)),"") -> 0
A7: P02 | L7: =IFERROR(INDEX(Participants!$T$6:$T$205,MATCH(A7,Participants!$A$6:$A$205,0)),"") -> 0
A8: P03 | L8: =IFERROR(INDEX(Participants!$T$6:$T$205,MATCH(A8,Participants!$A$6:$A$205,0)),"") -> 0
A9: P04 | L9: =IFERROR(INDEX(Participants!$T$6:$T$205,MATCH(A9,Participants!$A$6:$A$205,0)),"") -> 0
A10: P05 | L10: =IFERROR(INDEX(Participants!$T$6:$T$205,MATCH(A10,Participants!$A$6:$A$205,0)),"") -> 0
A11: P06 | L11: =IFERROR(INDEX(Participants!$T$6:$T$205,MATCH(A11,Participants!$A$6:$A$205,0)),"") -> 0
A12: P07 | L12: =IFERROR(INDEX(Participants!$T$6:$T$205,MATCH(A12,Participants!$A$6:$A$205,0)),"") -> 0
A13: P08 | L13: =IFERROR(INDEX(Participants!$T$6:$T$205,MATCH(A13,Participants!$A$6:$A$205,0)),"") -> 0
A14: P09 | L14: =IFERROR(INDEX(Participants!$T$6:$T$205,MATCH(A14,Participants!$A$6:$A$205,0)),"") -> 0
A15: P10 | L15: =IFERROR(INDEX(Participants!$T$6:$T$205,MATCH(A15,Participants!$A$6:$A$205,0)),"") -> 0
A16: P11 | L16: =IFERROR(INDEX(Participants!$T$6:$T$205,MATCH(A16,Participants!$A$6:$A$205,0)),"") -> 0
A17: P12 | L17: =IFERROR(INDEX(Participants!$T$6:$T$205,MATCH(A17,Participants!$A$6:$A$205,0)),"") -> 0
... A25: P20 | L25: =IFERROR(INDEX(Participants!$T$6:$T$205,MATCH(A25,Participants!$A$6:$A$205,0)),"") -> 0
L26: =IFERROR(INDEX(Participants!$T$6:$T$205,MATCH(A26,Participants!$A$6:$A$205,0)),"")
L27: =IFERROR(INDEX(Participants!$T$6:$T$205,MATCH(A27,Participants!$A$6:$A$205,0)),"")
L28: =IFERROR(INDEX(Participants!$T$6:$T$205,MATCH(A28,Participants!$A$6:$A$205,0)),"")
L29: =IFERROR(INDEX(Participants!$T$6:$T$205,MATCH(A29,Participants!$A$6:$A$205,0)),"")
L30: =IFERROR(INDEX(Participants!$T$6:$T$205,MATCH(A30,Participants!$A$6:$A$205,0)),"")
L31: =IFERROR(INDEX(Participants!$T$6:$T$205,MATCH(A31,Participants!$A$6:$A$205,0)),"")
L32: =IFERROR(INDEX(Participants!$T$6:$T$205,MATCH(A32,Participants!$A$6:$A$205,0)),"")
L33: =IFERROR(INDEX(Participants!$T$6:$T$205,MATCH(A33,Participants!$A$6:$A$205,0)),"")
L34: =IFERROR(INDEX(Participants!$T$6:$T$205,MATCH(A34,Participants!$A$6:$A$205,0)),"")
L35: =IFERROR(INDEX(Participants!$T$6:$T$205,MATCH(A35,Participants!$A$6:$A$205,0)),"")
L36: =IFERROR(INDEX(Participants!$T$6:$T$205,MATCH(A36,Participants!$A$6:$A$205,0)),"")
L37: =IFERROR(INDEX(Participants!$T$6:$T$205,MATCH(A37,Participants!$A$6:$A$205,0)),"")
... L205: =IFERROR(INDEX(Participants!$T$6:$T$205,MATCH(A205,Participants!$A$6:$A$205,0)),"")

Sheet Stops
A1: Stops — per-stop ratings (Test C)
A2: One row per rated stop. Weather: look it up afterwards for the stop time.
A3: Example (ignored by formulas) →
A4: P00 | B4: 2026-10-25 | C4: 2 | D4: Uber Boat, Westminster to Greenwich | E4: 11:40 | F4: 5 | G4: 17°C, dry | H4: 12 | I4: Y
A5: Participant | B5: Date | C5: Stop # | D5: Moment / place | E5: Time (hh:mm) | F5: Rating (1–5) | G5: Weather | H5: Travel time to it (min) | I5: Shot-card stop (Y/N) | J5: Notes | K5: channel | L5: rating | stranger
K6: =IFERROR(INDEX(Participants!$T$6:$T$205,MATCH(A6,Participants!$A$6:$A$205,0)),"") | L6: =IF(AND(K6="stranger",ISNUMBER(F6)),F6,"")
K7: =IFERROR(INDEX(Participants!$T$6:$T$205,MATCH(A7,Participants!$A$6:$A$205,0)),"") | L7: =IF(AND(K7="stranger",ISNUMBER(F7)),F7,"")
K8: =IFERROR(INDEX(Participants!$T$6:$T$205,MATCH(A8,Participants!$A$6:$A$205,0)),"") | L8: =IF(AND(K8="stranger",ISNUMBER(F8)),F8,"")
K9: =IFERROR(INDEX(Participants!$T$6:$T$205,MATCH(A9,Participants!$A$6:$A$205,0)),"") | L9: =IF(AND(K9="stranger",ISNUMBER(F9)),F9,"")
K10: =IFERROR(INDEX(Participants!$T$6:$T$205,MATCH(A10,Participants!$A$6:$A$205,0)),"") | L10: =IF(AND(K10="stranger",ISNUMBER(F10)),F10,"")
K11: =IFERROR(INDEX(Participants!$T$6:$T$205,MATCH(A11,Participants!$A$6:$A$205,0)),"") | L11: =IF(AND(K11="stranger",ISNUMBER(F11)),F11,"")
K12: =IFERROR(INDEX(Participants!$T$6:$T$205,MATCH(A12,Participants!$A$6:$A$205,0)),"") | L12: =IF(AND(K12="stranger",ISNUMBER(F12)),F12,"")
K13: =IFERROR(INDEX(Participants!$T$6:$T$205,MATCH(A13,Participants!$A$6:$A$205,0)),"") | L13: =IF(AND(K13="stranger",ISNUMBER(F13)),F13,"")
K14: =IFERROR(INDEX(Participants!$T$6:$T$205,MATCH(A14,Participants!$A$6:$A$205,0)),"") | L14: =IF(AND(K14="stranger",ISNUMBER(F14)),F14,"")
K15: =IFERROR(INDEX(Participants!$T$6:$T$205,MATCH(A15,Participants!$A$6:$A$205,0)),"") | L15: =IF(AND(K15="stranger",ISNUMBER(F15)),F15,"")
K16: =IFERROR(INDEX(Participants!$T$6:$T$205,MATCH(A16,Participants!$A$6:$A$205,0)),"") | L16: =IF(AND(K16="stranger",ISNUMBER(F16)),F16,"")
K17: =IFERROR(INDEX(Participants!$T$6:$T$205,MATCH(A17,Participants!$A$6:$A$205,0)),"") | L17: =IF(AND(K17="stranger",ISNUMBER(F17)),F17,"")
... K205: =IFERROR(INDEX(Participants!$T$6:$T$205,MATCH(A205,Participants!$A$6:$A$205,0)),"") | L205: =IF(AND(K205="stranger",ISNUMBER(F205)),F205,"")

Sheet Posts
A1: Recruitment posts (D21)
A2: Minutes = writing + posting + replying. Sign-ups = form rows with this post's src.
A3: Example (ignored by formulas) →
A4: A-03 | B4: A-C | C4: UCL Hiking Society | D4: Facebook | E4: 2026-10-15 | F4: 35 | G4: 4
A5: Post ID | B5: For | C5: Group | D5: Channel | E5: Date | F5: Minutes spent | G5: Sign-ups from it

Sheet Discovery
A1: Test E — B2B discovery interviews (D34)
A2: One row per interview (5 planned) or venue conversation. Past behaviour only; no pitching until the close.
A3: Example (ignored by formulas) →
A4: E00 | B4: hotel | C4: Guest experience manager | D4: 2026-10-21 | E4: 120 | F4: concierge knowledge + printed map | G4: 0 | H4: 6 | I4: Y | J4: "half our reviews mention the concierge tips" | K4: introduction | L4: group owner signs off guest-experience spend
A5: ID | B5: Type | C5: Role | D5: Date | E5: Guests or visitors per week | F5: What they use now | G5: Current spend (£/month, 0 if none) | H5: Staff time on it (hours/week) | I5: Budget owner named (Y/N) | J5: Strongest pain quote (verbatim) | K5: Commitment | L5: Notes

Sheet TestD
A1: Test D — landing page by arm (D25)
A2: From GoatCounter (/arm-A, /arm-B) and the Tally export. Exclude src=participant and src=ff (friends and family, D43; count them in row 15). Invitees = rows with a ref code.
A4: Line | B4: Arm A (£4.99/m, £49.99/yr) | C4: Arm B (£9.99/m, £99.99/yr) | D4: Total
A5: Visits | D5: =B5+C5 -> 0
A6: Sign-ups: free waitlist | D6: =B6+C6 -> 0
A7: Sign-ups: founding price, monthly | D7: =B7+C7 -> 0
A8: Sign-ups: founding price, annual | D8: =B8+C8 -> 0
A9: Of all sign-ups: invitees (had a ref code) | D9: =B9+C9 -> 0
A10: Sign-ups (all) | B10: =SUM(B6:B8) -> 0 | C10: =SUM(C6:C8) -> 0 | D10: =SUM(D6:D8) -> 0
A11: Sign-ups excl. invitees | B11: =B10-B9 -> 0 | C11: =C10-C9 -> 0 | D11: =D10-D9 -> 0
A12: Visit → sign-up (excl. invitees) | B12: =IF(B5>0,B11/B5,"no data") -> no data | C12: =IF(C5>0,C11/C5,"no data") -> no data | D12: =IF(D5>0,D11/D5,"no data") -> no data
A13: Sign-ups choosing a priced option | B13: =IF(B10>0,(B7+B8)/B10,"no data") -> no data | C13: =IF(C10>0,(C7+C8)/C10,"no data") -> no data | D13: =IF(D10>0,(D7+D8)/D10,"no data") -> no data
A14: Of priced: annual | B14: =IF((B7+B8)>0,B8/(B7+B8),"no data") -> no data | C14: =IF((C7+C8)>0,C8/(C7+C8),"no data") -> no data | D14: =IF((D7+D8)>0,D8/(D7+D8),"no data") -> no data
A15: Friends-and-family sign-ups (src=ff), not in any rate | D15: =B15+C15 -> 0
