Workbook

Sheet README
A1: Unit economics — moment-based travel planner (Phase 2)
A2: Built 2026-09-26. All money in GBP; USD prices converted at the ECB rate on Inputs. Sources: research/sources.csv (area "econ") and economics/assumptions.md.
A4: How to use
A5: Edit blue cells only: Inputs column C, PriceTables, and the stack choices at the top of Costs (rows 6-15).
A6: Black cells are formulas. Green cells link to another sheet or a named input. Yellow = key assumption Phase 3 must measure.
A7: Every input has a status: fetched, search, GUESS, LEVER, TARGET (Phase 3 threshold) or FOUNDER.
A8: No money can be taken until the legal gates clear (CLAUDE.md). Revenue here is what the model would earn after that.
A10: Tabs
A11: Inputs | B11: Every assumption with value, unit, status, source URL and date
A12: PriceTables | B12: Claude models and transcription services a stack can pick
A13: Costs | B13: Three stacks: onboarding, per-plan, per-user-month and fixed costs; WhatsApp vs Telegram
A14: Subscription / PerTrip / GroupTrip / Affiliate / Promoted | B14: One revenue model per tab: contribution per user and per trip
A15: CAC | B15: Cost per paying user by channel
A16: LTV | B16: Retention → LTV → LTV:CAC; value vs cost per sign-up for all five models
A17: BreakEven | B17: Break-even volumes; users needed for £10k, £50k, £100k a year; VAT threshold
A18: Sensitivity | B18: One-way table on key inputs; two-way price × conversion grid
A19: FounderHours | B19: Founder hours per 100 users and the capacity of 7.5 h a week
A21: Key results (live links)
A22: Line | B22: Cheapest | C22: Default | D22: Premium
A23: Onboarding cost per sign-up (£) | B23: =Costs!C29 -> 0.056595231 | C23: =Costs!D29 -> 0.3191971 | D23: =Costs!E29 -> 4.461968
A24: Cost per plan (£) | B24: =Costs!C35 -> 0.018311903 | C24: =Costs!D35 -> 0.08622618 | D24: =Costs!E35 -> 0.14599074
A25: Cash cost per paying user per month (£) | B25: =Costs!C41 -> 0.03347815 | C25: =Costs!D41 -> 0.14025449 | D25: =Costs!E41 -> 0.31309276
A26: Fixed cost per month (£) | B26: =Costs!C49 -> 15.143173 | C26: =Costs!D49 -> 24.953013 | D26: =Costs!E49 -> 83.05745
A27: Subscription: contribution per active payer-month (£) | B27: =Subscription!C26 -> 1.719124 | C27: =Subscription!D26 -> 1.6123476 | D27: =Subscription!E26 -> 2.428
A28: Subscription: blended LTV per new payer (£) | B28: =Subscription!C23 -> 25.668174 | C28: =Subscription!D23 -> 24.0739 | D28: =Subscription!E23 -> 36.252374
A29: Pay per plan: contribution per plan (£) | B29: =PerTrip!C11 -> 1.8372911 | C29: =PerTrip!D11 -> 1.7693768 | D29: =PerTrip!E11 -> 2.5991593
A30: Group trip: contribution per trip (£) | B30: =GroupTrip!C14 -> 14.981688 | C30: =GroupTrip!D14 -> 14.913774 | D30: =GroupTrip!E14 -> 14.614951
A31: Affiliate: contribution per plan (£) | B31: =Affiliate!C12 -> 0.065688097 | C31: =Affiliate!D12 -> -0.0022261797 | D31: =Affiliate!E12 -> -0.061990744
A32: Promoted: contribution per MAU-month (£) | B32: =Promoted!C12 -> 0.084833753 | C32: =Promoted!D12 -> 0.045971695 | D32: =Promoted!E12 -> 0.0092979849
A34: LTV:CAC, Default stack
A35: Organic community posts | C35: =LTV!C10 -> 1.3319581
A36: Referral | C36: =LTV!C11 -> 0.26062363
A37: Paid social: Meta | C37: =LTV!C12 -> 0.064159953
A38: Paid social: Reddit | C38: =LTV!C13 -> 0.063787321
A40: Sign-ups a year for £50k net (Default)
A41: Subscription | C41: =BreakEven!C18 -> 90987.054
A42: Pay per plan | C42: =BreakEven!C25 -> 134727.09
A43: Group-trip commission | C43: =BreakEven!C30 -> 43859.649
A44: Affiliate | C44: =BreakEven!C35 -> 396825.4 | E44: Affiliate and promoted rows are cumulative sign-ups, not per year
A45: Promoted experiences | C45: =BreakEven!C38 -> 166666.67

Sheet Inputs
A1: Inputs — every number the model uses. Edit the blue cells in column C only.
A2: Status: fetched = read on the source page; search = search result only; GUESS = our estimate; LEVER = a design choice; TARGET = a Phase 3 pass threshold; FOUNDER = from the founder brief. Yellow = key assumption that Phase 3 must measure.
A4: Name (used in formulas) | B4: Input | C4: Value | D4: Unit | E4: Status | F4: Source URL | G4: Accessed | H4: Note / what will measure it
A5: General
A6: fx | B6: Exchange rate | C6: 1.3252 | D6: USD per GBP | E6: fetched | F6: https://www.ecb.europa.eu/stats/eurofxref/eurofxref-daily.xml | G6: 2026-09-26 | H6: ECB reference rates 2026-09-25: EUR 1 = USD 1.1403 = GBP 0.86045
A7: vat_rate | B7: UK VAT standard rate | C7: 0.2 | D7: fraction | E7: fetched | F7: https://www.gov.uk/vat-rates | G7: 2026-09-26
A8: vat_threshold | B8: VAT registration threshold | C8: 90000 | D8: £ taxable turnover / 12 months | E8: fetched | F8: https://www.gov.uk/vat-registration/when-to-register | G8: 2026-09-26 | H8: BreakEven flags which revenue targets cross it
A9: vat_registered | B9: VAT registered? (1 = yes) | C9: 0 | D9: switch | E9: LEVER | H9: Set to 1 once turnover passes the threshold: then 1/6 of every VAT-inclusive Stripe sale goes to HMRC. Stars sales are left untaxed here: the app store sells the Stars (VAT treatment UNVERIFIED)
A10: founder_rate | B10: Shadow value of one founder hour | C10: 25 | D10: £ / hour | E10: GUESS | H10: Used only in the "incl. founder time" rows. Hours, not money, are the binding constraint
A11: ico_fee_year | B11: ICO data protection fee (tier 1) | C11: 52 | D11: £ / year | E11: search | F11: https://ico.org.uk/for-organisations/data-protection-fee/data-protection-fee/ | G11: 2026-09-26 | H11: Micro organisations; £5 off by direct debit
A12: domain_year | B12: Domain and email | C12: 12 | D12: £ / year | E12: GUESS
A13: Payments
A14: stripe_pct | B14: Stripe: percentage fee, standard UK cards | C14: 0.015 | D14: fraction of charge | E14: fetched | F14: https://stripe.com/gb/pricing | G14: 2026-09-26 | H14: 1.5% + 20p
A15: stripe_fixed | B15: Stripe: fixed fee per charge | C15: 0.2 | D15: £ per charge | E15: fetched | F15: https://stripe.com/gb/pricing | G15: 2026-09-26
A16: apple_commission | B16: Apple commission (Small Business Program) | C16: 0.15 | D16: fraction | E16: fetched | F16: https://developer.apple.com/app-store/small-business-program/ | G16: 2026-09-26 | H16: Only for a native iOS app with in-app purchase. No v0 stack uses one
A17: stars_dev_usd | B17: Telegram Stars: developer reward per Star | C17: 0.013 | D17: USD per Star | E17: fetched | F17: https://telegram.org/tos/bot-developers | G17: 2026-09-26 | H17: Developer Terms s.6.2.4. Digital goods sold inside Telegram must be paid in Stars (core.telegram.org/bots/payments-stars, fetched)
A18: stars_user_usd | B18: Telegram Stars: price a user pays per Star (app store) | C18: 0.0199 | D18: USD per Star | E18: fetched | F18: https://dev.to/starsearn/telegram-stars-economics-for-bot-developers-what-your-stars-are-actually-worth-in-2026-2742 | G18: 2026-09-26 | H18: Third-party estimate: ~$1.99 per 100 Stars via in-app purchase. Check before pricing
A19: stars_withdraw_fee | B19: Telegram Stars: withdrawal fee (Fragment, TON) | C19: 0.05 | D19: fraction | E19: search | F19: https://adminhub.tools/blog/withdraw-telegram-stars/ | G19: 2026-09-26 | H19: Plus TON exchange costs, not modelled
A20: Messaging
A21: tg_msg_usd | B21: Telegram: cost per bot message | C21: 0 | D21: USD per message | E21: fetched | F21: https://core.telegram.org/bots/faq | G21: 2026-09-26 | H21: Bots message users at no cost
A22: wa_utility_usd | B22: WhatsApp: UK utility template outside 24h window | C22: 0.022 | D22: USD per message | E22: search | F22: https://payperwa.com/blog/whatsapp-business-api-pricing-uk-2026 | G22: 2026-09-26 | H22: Third-party figure. Messages inside an open 24h service window are free (Meta, fetched)
A23: wa_marketing_gbp | B23: WhatsApp: UK marketing template | C23: 0.0382 | D23: £ per message | E23: search | F23: https://payperwa.com/blog/whatsapp-business-api-pricing-uk-2026 | G23: 2026-09-26 | H23: Third-party figure. Used for re-engagement messages
A24: wa_outside_window | B24: Share of in-trip messages sent outside the 24h window | C24: 0.3 | D24: fraction | E24: GUESS | H24: Rating prompts usually follow a user tap, so most fall inside the window
A25: Hosting and third-party services
A26: render_web_s | B26: Render web service, 512 MB | C26: 7 | D26: USD / month | E26: fetched | F26: https://render.com/pricing | G26: 2026-09-26
A27: render_web_l | B27: Render web service, 2 GB | C27: 25 | D27: USD / month | E27: fetched | F27: https://render.com/pricing | G27: 2026-09-26
A28: render_pg_s | B28: Render Postgres, 256 MB | C28: 6 | D28: USD / month | E28: fetched | F28: https://render.com/pricing | G28: 2026-09-26
A29: render_pg_l | B29: Render Postgres, 1 GB | C29: 19 | D29: USD / month | E29: fetched | F29: https://render.com/pricing | G29: 2026-09-26
A30: render_storage | B30: Render Postgres extra storage | C30: 0.3 | D30: USD / GB / month | E30: fetched | F30: https://render.com/pricing | G30: 2026-09-26 | H30: 1 GB included
A31: users_per_unit | B31: Active users served by one web + database unit | C31: 2000 | D31: users | E31: GUESS | H31: Adds one hosting unit per this many active users (conservative: counts the first unit twice)
A32: storage_mb_user | B32: Storage per user (transcripts, ratings, plans) | C32: 5 | D32: MB | E32: GUESS | H32: Raw audio is deleted after transcription (D3)
A33: mo_tier_gbp | B33: Met Office DataHub: first paid tier | C33: 9 | D33: £ / month | E33: fetched | F33: https://datahub.metoffice.gov.uk/pricing/site-specific | G33: 2026-09-26 | H33: 900 calls/day; free plan 360 calls/day (ex VAT)
A34: mo_tier_calls | B34: Met Office DataHub: calls per day in first paid tier | C34: 900 | D34: calls / day | E34: fetched | F34: https://datahub.metoffice.gov.uk/pricing/site-specific | G34: 2026-09-26
A35: mo_free_calls | B35: Met Office DataHub: free calls per day | C35: 360 | D35: calls / day | E35: fetched | F35: https://datahub.metoffice.gov.uk/pricing/site-specific | G35: 2026-09-26
A36: tavus_plan_usd | B36: Tavus Starter plan fee | C36: 59 | D36: USD / month | E36: fetched | F36: https://www.tavus.io/pricing | G36: 2026-09-26 | H36: Includes 100 min of conversational video, up to 3 concurrent streams
A37: tavus_incl_min | B37: Tavus Starter included minutes | C37: 100 | D37: minutes / month | E37: fetched | F37: https://www.tavus.io/pricing | G37: 2026-09-26 | H37: Model charges overage on every minute (conservative)
A38: tavus_overage_usd | B38: Tavus Starter overage | C38: 0.37 | D38: USD / minute | E38: fetched | F38: https://www.tavus.io/pricing | G38: 2026-09-26 | H38: Growth plan: $397/mo incl. 1,250 min, then $0.32/min
A39: aura2_usd_1k | B39: Deepgram Aura-2 text-to-speech | C39: 0.03 | D39: USD / 1,000 characters | E39: fetched | F39: https://deepgram.com/pricing | G39: 2026-09-26
A40: Onboarding usage (per sign-up)
A41: voice_share | B41: Share of users who answer by voice | C41: 0.5 | D41: fraction | E41: GUESS | H41: Test A records this (D4). Premium stack is always voice
...

Sheet PriceTables
A1: Price tables — models and transcription services a stack can pick (Costs rows 6-7)
B3: Claude API (USD per million tokens, standard; Batch API is 50% off)
B4: Model | C4: Input | D4: Output | E4: Cache read | F4: Status | G4: Source URL | H4: Accessed
B5: Claude Haiku 4.5 | C5: 1 | D5: 5 | E5: 0.1 | F5: fetched | G5: https://platform.claude.com/docs/en/about-claude/pricing | H5: 2026-09-26
B6: Claude Sonnet 5 | C6: 2 | D6: 10 | E6: 0.2 | F6: fetched | G6: https://platform.claude.com/docs/en/about-claude/pricing | H6: 2026-09-26
B7: Claude Opus 5 | C7: 5 | D7: 25 | E7: 0.5 | F7: fetched | G7: https://platform.claude.com/docs/en/about-claude/pricing | H7: 2026-09-26
B8: Claude Opus 5.5 | C8: 4 | D8: 20 | E8: 0.2 | F8: fetched | G8: https://platform.claude.com/docs/en/about-claude/pricing | H8: 2026-09-26
B10: Sonnet 5 at $2/$10 is now the standard price (the $3/$15 rise was cancelled). Opus 5.5 cache hits are 0.05x input.
B12: Transcription (USD per audio minute, file/pre-recorded)
B13: Service | C13: USD / min | F13: Status | G13: Source URL | H13: Accessed
B14: gpt-4o-mini-transcribe | C14: 0.003 | F14: fetched | G14: https://developers.openai.com/api/docs/pricing | H14: 2026-09-26
B15: gpt-transcribe | C15: 0.0045 | F15: fetched | G15: https://developers.openai.com/api/docs/pricing | H15: 2026-09-26
B16: gpt-4o-transcribe | C16: 0.006 | F16: fetched | G16: https://developers.openai.com/api/docs/pricing | H16: 2026-09-26
B17: Deepgram Nova-3 | C17: 0.0043 | F17: fetched | G17: https://deepgram.com/pricing | H17: 2026-09-26
B19: Whisper-family models invent text in ~1% of transcripts, so v0 reads back what it heard (Area 1).

Sheet Costs
A1: Costs per user for three stacks (GBP)
A2: Stack choices in rows 6-15 are levers. Everything else is a formula of Inputs and PriceTables.
A4: Line | B4: Unit | C4: Cheapest | D4: Default | E4: Premium | F4: Note
A5: Stack choices (edit the blue cells)
A6: Stack | B6: text | C6: Telegram, text or recorded clips, small model | D6: Telegram, voice host, frontier model | E6: Web live avatar, WhatsApp in trip | F6: Kickoff: cheapest = Telegram + small models; premium = live avatar
A7: LLM | B7: model | C7: Claude Haiku 4.5 | D7: Claude Opus 5 | E7: Claude Opus 5 | F7: Pick from PriceTables. Opus 5.5 ($4/$20) is cheaper than Opus 5
A8: Transcription | B8: service | C8: gpt-4o-mini-transcribe | D8: gpt-transcribe | E8: gpt-4o-transcribe | F8: Pick from PriceTables
A9: Share answering by voice | B9: fraction | C9: =voice_share -> 0.5 | D9: =voice_share -> 0.5 | E9: 1 | F9: A live avatar is a voice conversation
A10: Host speaks with synthetic voice (1 = yes) | B10: switch | C10: 0 | D10: 1 | E10: 0 | F10: Cheapest: text questions or pre-recorded human clips (one-off cost, not per user)
A11: Live avatar host (1 = yes) | B11: switch | C11: 0 | D11: 0 | E11: 1 | F11: Tavus conversational video
A12: In-trip channel is WhatsApp (1 = yes) | B12: switch | C12: 0 | D12: 0 | E12: 1 | F12: 0 = Telegram
A13: Share of digital sales paid in Telegram Stars | B13: fraction | C13: 1 | D13: 1 | E13: 0 | F13: Telegram requires Stars for digital goods sold inside Telegram. Premium sells on the web through Stripe
A14: Web service | B14: USD / month | C14: =render_web_s -> 7 | D14: =render_web_s -> 7 | E14: =render_web_l -> 25
A15: Postgres | B15: USD / month | C15: =render_pg_s -> 6 | D15: =render_pg_l -> 19 | E15: =render_pg_l -> 19
A16: Unit prices looked up for this stack
A17: LLM input price | B17: USD / MTok | C17: =INDEX(llm_in,MATCH(C7,llm_names,0)) -> 1 | D17: =INDEX(llm_in,MATCH(D7,llm_names,0)) -> 5 | E17: =INDEX(llm_in,MATCH(E7,llm_names,0)) -> 5
A18: LLM output price | B18: USD / MTok | C18: =INDEX(llm_out,MATCH(C7,llm_names,0)) -> 5 | D18: =INDEX(llm_out,MATCH(D7,llm_names,0)) -> 25 | E18: =INDEX(llm_out,MATCH(E7,llm_names,0)) -> 25
A19: Transcription price | B19: USD / min | C19: =INDEX(tr_usd,MATCH(C8,tr_names,0)) -> 0.003 | D19: =INDEX(tr_usd,MATCH(D8,tr_names,0)) -> 0.0045 | E19: =INDEX(tr_usd,MATCH(E8,tr_names,0)) -> 0.006
A20: Cost per bot message | B20: £ | C20: =IF(C12=1,wa_outside_window*wa_utility_usd/fx,tg_msg_usd/fx) -> 0 | D20: =IF(D12=1,wa_outside_window*wa_utility_usd/fx,tg_msg_usd/fx) -> 0 | E20: =IF(E12=1,wa_outside_window*wa_utility_usd/fx,tg_msg_usd/fx) -> 0.0049803803 | F20: WhatsApp: free inside the 24h window
A21: Weather cost per call (paid-tier rate) | B21: £ | C21: =mo_tier_gbp/(mo_tier_calls*30) -> 0.00033333333 | D21: =mo_tier_gbp/(mo_tier_calls*30) -> 0.00033333333 | E21: =mo_tier_gbp/(mo_tier_calls*30) -> 0.00033333333 | F21: Zero while under 360 calls a day
A22: Stars: share of the user's price we receive | B22: fraction | C22: =stars_dev_usd*(1-stars_withdraw_fee)/stars_user_usd -> 0.62060302 | D22: =stars_dev_usd*(1-stars_withdraw_fee)/stars_user_usd -> 0.62060302 | E22: =stars_dev_usd*(1-stars_withdraw_fee)/stars_user_usd -> 0.62060302 | F22: The app store, Telegram and the withdrawal take the rest
A23: Onboarding cost per sign-up
A24: Transcription | B24: £ | C24: =C9*onb_speech_min*C19/fx -> 0.0090552369 | D24: =D9*onb_speech_min*D19/fx -> 0.013582855 | E24: =E9*onb_speech_min*E19/fx -> 0.036220948
A25: LLM follow-ups and extraction | B25: £ | C25: =(onb_in_tokens*C17+onb_out_tokens*C18)/1000000/fx -> 0.047539994 | D25: =(onb_in_tokens*D17+onb_out_tokens*D18)/1000000/fx -> 0.23769997 | E25: =(onb_in_tokens*E17+onb_out_tokens*E18)/1000000/fx -> 0.23769997
A26: Host voice (text-to-speech) | B26: £ | C26: =C10*onb_host_chars/1000*aura2_usd_1k/fx -> 0 | D26: =D10*onb_host_chars/1000*aura2_usd_1k/fx -> 0.067914277 | E26: =E10*onb_host_chars/1000*aura2_usd_1k/fx -> 0
A27: Live avatar video | B27: £ | C27: =C11*onb_session_min*tavus_overage_usd/fx -> 0 | D27: =D11*onb_session_min*tavus_overage_usd/fx -> 0 | E27: =E11*onb_session_min*tavus_overage_usd/fx -> 4.1880471 | F27: Whole session is billed, listening included
A28: Image embeddings | B28: £ | C28: =onb_embed_gbp -> 0 | D28: =onb_embed_gbp -> 0 | E28: =onb_embed_gbp -> 0 | F28: D16
A29: Total onboarding cost per sign-up | B29: £ | C29: =SUM(C24:C28) -> 0.056595231 | D29: =SUM(D24:D28) -> 0.3191971 | E29: =SUM(E24:E28) -> 4.461968
A30: Cost per plan
A31: LLM (candidate scoring context, explanations) | B31: £ | C31: =(plan_in_tokens*C17+plan_out_tokens*C18)/1000000/fx -> 0.016978569 | D31: =(plan_in_tokens*D17+plan_out_tokens*D18)/1000000/fx -> 0.084892846 | E31: =(plan_in_tokens*E17+plan_out_tokens*E18)/1000000/fx -> 0.084892846 | F31: The solver (OR-Tools) runs on our server
A32: Weather | B32: £ | C32: =plan_weather_calls*C21 -> 0.0013333333 | D32: =plan_weather_calls*D21 -> 0.0013333333 | E32: =plan_weather_calls*E21 -> 0.0013333333
A33: Routing and places | B33: £ | C33: =plan_routing_gbp -> 0 | D33: =plan_routing_gbp -> 0 | E33: =plan_routing_gbp -> 0
A34: Messages (delivery, nudges, rating prompts) | B34: £ | C34: =plan_msgs*C20 -> 0 | D34: =plan_msgs*D20 -> 0 | E34: =plan_msgs*E20 -> 0.059764564
A35: Total cost per plan | B35: £ | C35: =SUM(C31:C34) -> 0.018311903 | D35: =SUM(D31:D34) -> 0.08622618 | E35: =SUM(E31:E34) -> 0.14599074
A36: Cost per active paying user per month
A37: Plans | B37: £ | C37: =plans_per_payer*C35 -> 0.027467854 | D37: =plans_per_payer*D35 -> 0.12933927 | E37: =plans_per_payer*E35 -> 0.21898612
A38: Re-engagement messages | B38: £ | C38: =C12*reengage_msgs*wa_marketing_gbp -> 0 | D38: =D12*reengage_msgs*wa_marketing_gbp -> 0 | E38: =E12*reengage_msgs*wa_marketing_gbp -> 0.0764
A39: Storage | B39: £ | C39: =storage_mb_user/1024*render_storage/fx -> 0.0011053756 | D39: =storage_mb_user/1024*render_storage/fx -> 0.0011053756 | E39: =storage_mb_user/1024*render_storage/fx -> 0.0011053756
A40: Hosting (per-user share of extra units) | B40: £ | C40: =(C14+C15)/fx/users_per_unit -> 0.00490492 | D40: =(D14+D15)/fx/users_per_unit -> 0.00980984 | E40: =(E14+E15)/fx/users_per_unit -> 0.016601268
A41: Total cash cost per payer-month | B41: £ | C41: =SUM(C37:C40) -> 0.03347815 | D41: =SUM(D37:D40) -> 0.14025449 | E41: =SUM(E37:E40) -> 0.31309276
...

Sheet Subscription
A1: Revenue model 1: subscription (monthly or annual)
A2: Freemium: onboarding + one free plan, then pay. Conversion and retention are RevenueCat 2026 medians.
A4: Line | B4: Unit | C4: Cheapest | D4: Default | E4: Premium | F4: Note
A5: Prices and payment costs
A6: Monthly price | B6: £ | C6: =price_month -> 4.99 | D6: =price_month -> 4.99 | E6: =price_month -> 4.99
A7: Annual price | B7: £ | C7: =price_year -> 29.99 | D7: =price_year -> 29.99 | E7: =price_year -> 29.99
A8: Share paid in Telegram Stars | B8: fraction | C8: =Costs!C13 -> 1 | D8: =Costs!D13 -> 1 | E8: =Costs!E13 -> 0
A9: Stars: share of price received | B9: fraction | C9: =Costs!C22 -> 0.62060302 | D9: =Costs!D22 -> 0.62060302 | E9: =Costs!E22 -> 0.62060302
A10: Net received per monthly payment | B10: £ | C10: =C8*C6*C9+(1-C8)*(C6/(1+vat_rate*vat_registered)-(C6*stripe_pct+stripe_fixed)) -> 3.096809 | D10: =D8*D6*D9+(1-D8)*(D6/(1+vat_rate*vat_registered)-(D6*stripe_pct+stripe_fixed)) -> 3.096809 | E10: =E8*E6*E9+(1-E8)*(E6/(1+vat_rate*vat_registered)-(E6*stripe_pct+stripe_fixed)) -> 4.71515 | F10: Stars: after store, Telegram and withdrawal. Stripe: after VAT (if registered) and 1.5% + 20p
A11: Net received per annual payment | B11: £ | C11: =C8*C7*C9+(1-C8)*(C7/(1+vat_rate*vat_registered)-(C7*stripe_pct+stripe_fixed)) -> 18.611884 | D11: =D8*D7*D9+(1-D8)*(D7/(1+vat_rate*vat_registered)-(D7*stripe_pct+stripe_fixed)) -> 18.611884 | E11: =E8*E7*E9+(1-E8)*(E7/(1+vat_rate*vat_registered)-(E7*stripe_pct+stripe_fixed)) -> 29.34015
A12: Contribution
A13: Cash cost per payer-month | B13: £ | C13: =Costs!C41 -> 0.03347815 | D13: =Costs!D41 -> 0.14025449 | E13: =Costs!E41 -> 0.31309276
A14: Contribution per monthly payer per month | B14: £ | C14: =C10-C13 -> 3.0633309 | D14: =D10-D13 -> 2.9565546 | E14: =E10-E13 -> 4.4020572
A15: Contribution per annual payer per year | B15: £ | C15: =C11-12*C13 -> 18.210147 | D15: =D11-12*D13 -> 16.928831 | E15: =E11-12*E13 -> 25.583037
A16: Contribution margin, monthly plan | B16: % of price | C16: =C14/C6 -> 0.61389397 | D16: =D14/D6 -> 0.5924959 | E16: =E14/E6 -> 0.8821758
A17: Retention to LTV
A18: Monthly plan: share still paying each month | B18: fraction | C18: =ret_monthly^(1/12) -> 0.82540419 | D18: =ret_monthly^(1/12) -> 0.82540419 | E18: =ret_monthly^(1/12) -> 0.82540419 | F18: Constant churn implied by year-one retention
A19: Expected paid months, monthly plan | B19: months | C19: =1/(1-C18) -> 5.7275142 | D19: =1/(1-D18) -> 5.7275142 | E19: =1/(1-E18) -> 5.7275142 | F19: Geometric lifetime, no cap
A20: Expected paid years, annual plan | B20: years | C20: =1/(1-ret_annual) -> 1.6393443 | D20: =1/(1-ret_annual) -> 1.6393443 | E20: =1/(1-ret_annual) -> 1.6393443
A21: LTV per monthly payer | B21: £ | C21: =C14*C19 -> 17.545271 | D21: =D14*D19 -> 16.933708 | E21: =E14*E19 -> 25.212845
A22: LTV per annual payer | B22: £ | C22: =C15*C20 -> 29.852699 | D22: =D15*D20 -> 27.752181 | E22: =E15*E20 -> 41.939405
A23: Blended LTV per new payer (contribution) | B23: £ | C23: =annual_share*C22+(1-annual_share)*C21 -> 25.668174 | D23: =annual_share*D22+(1-annual_share)*D21 -> 24.0739 | E23: =annual_share*E22+(1-annual_share)*E21 -> 36.252374 | F23: Used for LTV:CAC
A24: Lifetime net revenue per new payer | B24: £ | C24: =annual_share*C11*C20+(1-annual_share)*C10*C19 -> 26.168035 | D24: =annual_share*D11*D20+(1-annual_share)*D10*D19 -> 26.168035 | E24: =annual_share*E11*E20+(1-annual_share)*E10*E19 -> 40.92715 | F24: Used for revenue targets
A25: Expected paid months per new payer, blended | B25: months | C25: =annual_share*12*C20+(1-annual_share)*C19 -> 14.930961 | D25: =annual_share*12*D20+(1-annual_share)*D19 -> 14.930961 | E25: =annual_share*12*E20+(1-annual_share)*E19 -> 14.930961
A26: Contribution per active payer per month | B26: £ | C26: =C23/C25 -> 1.719124 | D26: =D23/D25 -> 1.6123476 | E26: =E23/E25 -> 2.428 | F26: Used for break-even
A27: Contribution per plan (trip) | B27: £ | C27: =C26/plans_per_payer -> 1.1460827 | D27: =D26/plans_per_payer -> 1.0748984 | E27: =E26/plans_per_payer -> 1.6186667
A28: Contribution per payer-month incl. founder time | B28: £ | C28: =C26-support_min/60*founder_rate -> 0.46912398 | D28: =D26-support_min/60*founder_rate -> 0.36234765 | E28: =E26-support_min/60*founder_rate -> 1.178 | F28: Negative = founder time costs more than the margin

Sheet PerTrip
A1: Revenue model 2: pay per plan (trip)
A2: Plans sold inside Telegram are digital services, so they are paid in Stars.
A4: Line | B4: Unit | C4: Cheapest | D4: Default | E4: Premium | F4: Note
A5: Per plan
A6: Fee per plan | B6: £ | C6: =trip_fee -> 2.99 | D6: =trip_fee -> 2.99 | E6: =trip_fee -> 2.99
A7: Share paid in Telegram Stars | B7: fraction | C7: =Costs!C13 -> 1 | D7: =Costs!D13 -> 1 | E7: =Costs!E13 -> 0
A8: Net received per plan | B8: £ | C8: =C7*C6*Costs!C22+(1-C7)*(C6/(1+vat_rate*vat_registered)-(C6*stripe_pct+stripe_fixed)) -> 1.855603 | D8: =D7*D6*Costs!D22+(1-D7)*(D6/(1+vat_rate*vat_registered)-(D6*stripe_pct+stripe_fixed)) -> 1.855603 | E8: =E7*E6*Costs!E22+(1-E7)*(E6/(1+vat_rate*vat_registered)-(E6*stripe_pct+stripe_fixed)) -> 2.74515
A9: Stripe 20p as a share of the fee | B9: fraction | C9: =stripe_fixed/C6 -> 0.066889632 | D9: =stripe_fixed/D6 -> 0.066889632 | E9: =stripe_fixed/E6 -> 0.066889632 | F9: Why small tickets suit plan packs
A10: Cost per plan | B10: £ | C10: =Costs!C35 -> 0.018311903 | D10: =Costs!D35 -> 0.08622618 | E10: =Costs!E35 -> 0.14599074
A11: Contribution per plan (trip) | B11: £ | C11: =C8-C10 -> 1.8372911 | D11: =D8-D10 -> 1.7693768 | E11: =E8-E10 -> 2.5991593
A12: Contribution margin | B12: % of fee | C12: =C11/C6 -> 0.61447863 | D12: =D11/D6 -> 0.59176483 | E12: =E11/E6 -> 0.86928403
A13: Per buyer
A14: Contribution per buyer per year | B14: £ | C14: =C11*trips_per_buyer -> 7.3491644 | D14: =D11*trips_per_buyer -> 7.0775073 | E14: =E11*trips_per_buyer -> 10.396637 | F14: No retention data: one-year value only
A15: Founder support per buyer per year | B15: hours | C15: =support_min/60*trips_per_buyer -> 0.2 | D15: =support_min/60*trips_per_buyer -> 0.2 | E15: =support_min/60*trips_per_buyer -> 0.2 | F15: One support contact per plan
A16: Contribution per buyer per year incl. founder time | B16: £ | C16: =C14-C15*founder_rate -> 2.3491644 | D16: =D14-D15*founder_rate -> 2.0775073 | E16: =E14-E15*founder_rate -> 5.396637

Sheet GroupTrip
A1: Revenue model 3: commission on group trips
A2: Blocked until the legal gates clear. Handling other people's money needs a licensed marketplace payment provider.
A4: Line | B4: Unit | C4: Cheapest | D4: Default | E4: Premium | F4: Note
A5: Per group trip
A6: Attendees | B6: people | C6: =group_size -> 5 | D6: =group_size -> 5 | E6: =group_size -> 5
A7: Spend per attendee | B7: £ | C7: =group_spend -> 40 | D7: =group_spend -> 40 | E7: =group_spend -> 40
A8: Money collected | B8: £ | C8: =C6*C7 -> 200 | D8: =D6*D7 -> 200 | E8: =E6*E7 -> 200 | F8: Real-world services: card payments allowed, not Stars
A9: Commission (net of VAT if registered) | B9: £ | C9: =C8*group_commission/(1+vat_rate*vat_registered) -> 20 | D9: =D8*group_commission/(1+vat_rate*vat_registered) -> 20 | E9: =E8*group_commission/(1+vat_rate*vat_registered) -> 20
A10: Commission lost to refunds | B10: £ | C10: =-C9*refund_rate -> -1 | D10: =-D9*refund_rate -> -1 | E10: =-E9*refund_rate -> -1
A11: Card fees on all money collected | B11: £ | C11: =-C6*(C7*stripe_pct+stripe_fixed) -> -4 | D11: =-D6*(D7*stripe_pct+stripe_fixed) -> -4 | E11: =-E6*(E7*stripe_pct+stripe_fixed) -> -4 | F11: The platform pays processing on the full amount
A12: Plan cost (one shared plan) | B12: £ | C12: =-Costs!C35 -> -0.018311903 | D12: =-Costs!D35 -> -0.08622618 | E12: =-Costs!E35 -> -0.14599074
A13: Messages to the other attendees | B13: £ | C13: =-(C6-1)*Costs!C34 -> 0 | D13: =-(D6-1)*Costs!D34 -> 0 | E13: =-(E6-1)*Costs!E34 -> -0.23905826
A14: Contribution per group trip | B14: £ | C14: =SUM(C9:C13) -> 14.981688 | D14: =SUM(D9:D13) -> 14.913774 | E14: =SUM(E9:E13) -> 14.614951
A15: Contribution per attendee | B15: £ | C15: =C14/C6 -> 2.9963376 | D15: =D14/D6 -> 2.9827548 | E15: =E14/E6 -> 2.9229902
A16: Take rate after costs | B16: % of money collected | C16: =C14/C8 -> 0.07490844 | D16: =D14/D8 -> 0.074568869 | E16: =E14/E8 -> 0.073074755
A17: Moderation per trip | B17: hours | C17: =group_mod_min/60 -> 0.5 | D17: =group_mod_min/60 -> 0.5 | E17: =group_mod_min/60 -> 0.5
A18: Contribution per trip incl. founder time | B18: £ | C18: =C14-C17*founder_rate -> 2.4816881 | D18: =D14-D17*founder_rate -> 2.4137738 | E18: =E14-E17*founder_rate -> 2.114951
A19: Net revenue per trip (for targets) | B19: £ | C19: =C9+C10 -> 19 | D19: =D9+D10 -> 19 | E19: =E9+E10 -> 19

Sheet Affiliate
A1: Revenue model 4: affiliate commission on bookable experiences
A2: Booking.com (25-40% of its own commission, search) is left out: London day trips need no hotel.
A4: Line | B4: Unit | C4: Cheapest | D4: Default | E4: Premium | F4: Note
A5: Per plan (plans free to the user)
A6: Plans with a bookable paid experience | B6: fraction | C6: =aff_plan_share -> 0.3 | D6: =aff_plan_share -> 0.3 | E6: =aff_plan_share -> 0.3
A7: Booking rate | B7: fraction | C7: =aff_click_book -> 0.1 | D7: =aff_click_book -> 0.1 | E7: =aff_click_book -> 0.1
A8: Average ticket | B8: £ | C8: =aff_ticket -> 35 | D8: =aff_ticket -> 35 | E8: =aff_ticket -> 35
A9: Commission rate | B9: fraction | C9: =aff_commission -> 0.08 | D9: =aff_commission -> 0.08 | E9: =aff_commission -> 0.08 | F9: Viator 8% (fetched), GetYourGuide 8% (search)
A10: Revenue per plan | B10: £ | C10: =C6*C7*C8*C9 -> 0.084 | D10: =D6*D7*D8*D9 -> 0.084 | E10: =E6*E7*E8*E9 -> 0.084
A11: Cost per plan | B11: £ | C11: =Costs!C35 -> 0.018311903 | D11: =Costs!D35 -> 0.08622618 | E11: =Costs!E35 -> 0.14599074
A12: Contribution per plan (trip) | B12: £ | C12: =C10-C11 -> 0.065688097 | D12: =D10-D11 -> -0.0022261797 | E12: =E10-E11 -> -0.061990744
A13: Per active user
A14: Hosting and storage per active user | B14: £ / month | C14: =Costs!C40+Costs!C39 -> 0.0060102956 | D14: =Costs!D40+Costs!D39 -> 0.010915216 | E14: =Costs!E40+Costs!E39 -> 0.017706643
A15: Contribution per active user per month | B15: £ | C15: =mau_plans*C12-C14 -> 0.026833753 | D15: =mau_plans*D12-D14 -> -0.012028305 | E15: =mau_plans*E12-E14 -> -0.048702015
A16: Revenue per plan if every stop were bookable | B16: £ | C16: =C7*C8*C9 -> 0.28 | D16: =D7*D8*D9 -> 0.28 | E16: =E7*E8*E9 -> 0.28 | F16: Pull toward paid stops: a conflict with a free-moment product

Sheet Promoted
A1: Revenue model 5: promoted experiences (CPM)
A2: Sponsored moments must be labelled as ads, and a paid slot competes with the predicted-feeling ranking.
A4: Line | B4: Unit | C4: Cheapest | D4: Default | E4: Premium | F4: Note
A5: Per monthly active user (MAU)
A6: CPM | B6: £ | C6: =cpm -> 5 | D6: =cpm -> 5 | E6: =cpm -> 5
A7: Promoted impressions per MAU per month | B7: impressions | C7: =impr_mau -> 20 | D7: =impr_mau -> 20 | E7: =impr_mau -> 20
A8: Fill rate | B8: fraction | C8: =fill_rate -> 1 | D8: =fill_rate -> 1 | E8: =fill_rate -> 1
A9: Revenue per MAU per month | B9: £ | C9: =C6/1000*C7*C8 -> 0.1 | D9: =D6/1000*D7*D8 -> 0.1 | E9: =E6/1000*E7*E8 -> 0.1
A10: Revenue per MAU per year | B10: £ | C10: =C9*12 -> 1.2 | D10: =D9*12 -> 1.2 | E10: =E9*12 -> 1.2
A11: Cost per MAU per month | B11: £ | C11: =mau_plans*Costs!C35+Costs!C40+Costs!C39 -> 0.015166247 | D11: =mau_plans*Costs!D35+Costs!D40+Costs!D39 -> 0.054028305 | E11: =mau_plans*Costs!E35+Costs!E40+Costs!E39 -> 0.090702015
A12: Contribution per MAU per month | B12: £ | C12: =C9-C11 -> 0.084833753 | D12: =D9-D11 -> 0.045971695 | E12: =E9-E11 -> 0.0092979849
A13: Contribution per plan (trip) | B13: £ | C13: =C12/mau_plans -> 0.16966751 | D13: =D12/mau_plans -> 0.091943389 | E13: =E12/mau_plans -> 0.01859597
A14: Reality check from the brief (£100k a year)
A15: Impressions a year for £100k | B15: impressions | C15: =100000/(C6/1000) -> 20000000 | D15: =100000/(D6/1000) -> 20000000 | E15: =100000/(E6/1000) -> 20000000 | F15: Brief: ~20m
A16: MAU needed for £100k | B16: MAU | C16: =C15/(C7*12*C8) -> 83333.333 | D16: =D15/(D7*12*D8) -> 83333.333 | E16: =E15/(E7*12*E8) -> 83333.333 | F16: Brief: ~83k

Sheet CAC
A1: Customer acquisition cost (CAC) per paying user, by channel
A2: CAC = (channel cost per sign-up + onboarding and free-plan cost per sign-up) ÷ sign-up-to-paying conversion.
A4: Channel | B4: Cash per sign-up (£) | C4: Founder h per sign-up | D4: Conversion to paying | E4: CAC Cheapest (£) | F4: CAC Default (£) | G4: CAC Premium (£) | H4: Founder h per payer | I4: CAC Default incl. founder time (£) | J4: Source / note
A5: Organic community posts | B5: 0 | C5: =post_hours/signups_post -> 0.1 | D5: =conv_paid -> 0.021 | E5: =($B5+Costs!C51)/$D5 -> 3.3054077 | F5: =($B5+Costs!D51)/$D5 -> 18.074068 | G5: =($B5+Costs!E51)/$D5 -> 217.34103 | H5: =C5/D5 -> 4.7619048 | I5: =F5+H5*founder_rate -> 137.12169 | J5: Recruitment posts for Tests A-D measure sign-ups per post (D21)
A6: Referral | B6: =ref_reward*onb_completion -> 3.5 | C6: 0 | D6: =conv_paid*ref_conv_mult -> 0.042 | E6: =($B6+Costs!C51)/$D6 -> 84.986037 | F6: =($B6+Costs!D51)/$D6 -> 92.370367 | G6: =($B6+Costs!E51)/$D6 -> 192.00385 | H6: =C6/D6 -> 0 | I6: =F6+H6*founder_rate -> 92.370367 | J6: Reward and uplift are guesses
A7: Paid social: Meta | B7: =meta_cpc/click_signup -> 7.5 | C7: 0 | D7: =conv_paid -> 0.021 | E7: =($B7+Costs!C51)/$D7 -> 360.44826 | F7: =($B7+Costs!D51)/$D7 -> 375.21693 | G7: =($B7+Costs!E51)/$D7 -> 574.48388 | H7: =C7/D7 -> 0 | I7: =F7+H7*founder_rate -> 375.21693 | J7: CPC £0.45-1.10 (third-party, fetched); visit to sign-up at the 10% Phase 3 threshold
A8: Paid social: Reddit | B8: =reddit_cpc_usd/fx/click_signup -> 7.5460308 | C8: 0 | D8: =conv_paid -> 0.021 | E8: =($B8+Costs!C51)/$D8 -> 362.64021 | F8: =($B8+Costs!D51)/$D8 -> 377.40887 | G8: =($B8+Costs!E51)/$D8 -> 576.67582 | H8: =C8/D8 -> 0 | I8: =F8+H8*founder_rate -> 377.40887 | J8: CPC $0.50-3.00 (third-party, fetched)
A10: Hard paywall: Meta CAC, Default stack | F10: =($B7+Costs!D51)/conv_paywall -> 73.640705 | J10: Hard paywalls convert 10.7% vs 2.1% (RevenueCat, fetched), with near-identical year-one retention
A12: Organic posting costs no cash but ~5 founder hours per paying user at base inputs. That is the binding constraint.

Sheet LTV
A1: Retention → LTV → LTV:CAC
A2: Subscription LTV from year-one retention (RevenueCat 2026). Payback = CAC ÷ contribution per active payer-month.
A4: Line | B4: Cheapest | C4: Default | D4: Premium
A5: Blended LTV per new payer (£) | B5: =Subscription!C23 -> 25.668174 | C5: =Subscription!D23 -> 24.0739 | D5: =Subscription!E23 -> 36.252374
A6: Contribution per active payer-month (£) | B6: =Subscription!C26 -> 1.719124 | C6: =Subscription!D26 -> 1.6123476 | D6: =Subscription!E26 -> 2.428
A8: LTV:CAC by channel
A9: Channel | B9: Cheapest | C9: Default | D9: Premium | E9: Payback months (Default) | F9: Default vs target
A10: Organic community posts | B10: =B$5/CAC!E5 -> 7.765509 | C10: =C$5/CAC!F5 -> 1.3319581 | D10: =D$5/CAC!G5 -> 0.1667995 | E10: =IF(C$6>0,CAC!F5/C$6,"never") -> 11.209783 | F10: =IF(C10>=ltv_cac_target,"meets","below") -> below
A11: Referral | B11: =B$5/CAC!E6 -> 0.30202813 | C11: =C$5/CAC!F6 -> 0.26062363 | D11: =D$5/CAC!G6 -> 0.18881067 | E11: =IF(C$6>0,CAC!F6/C$6,"never") -> 57.289362 | F11: =IF(C11>=ltv_cac_target,"meets","below") -> below
A12: Paid social: Meta | B12: =B$5/CAC!E7 -> 0.071211811 | C12: =C$5/CAC!F7 -> 0.064159953 | D12: =D$5/CAC!G7 -> 0.06310425 | E12: =IF(C$6>0,CAC!F7/C$6,"never") -> 232.71465 | F12: =IF(C12>=ltv_cac_target,"meets","below") -> below
A13: Paid social: Reddit | B13: =B$5/CAC!E8 -> 0.070781378 | C13: =C$5/CAC!F8 -> 0.063787321 | D13: =D$5/CAC!G8 -> 0.062864391 | E13: =IF(C$6>0,CAC!F8/C$6,"never") -> 234.07413 | F13: =IF(C13>=ltv_cac_target,"meets","below") -> below
A14: Paid social: Meta, hard paywall | C14: =C5/CAC!F10 -> 0.32691024 | E14: =IF(C$6>0,CAC!F10/C$6,"never") -> 45.67297 | F14: =IF(C14>=ltv_cac_target,"meets","below") -> below
A17: Value per sign-up vs cost per sign-up, all five models (Default stack, year one, Meta)
A18: Model | B18: Value per sign-up (£) | C18: Cost per sign-up via Meta (£) | D18: Ratio | E18: Basis
A19: Subscription | B19: =conv_paid*Subscription!D23 -> 0.50555191 | C19: =(CAC!$B$7+Costs!$D$51) -> 7.8795554 | D19: =B19/C19 -> 0.064159953 | E19: Lifetime contribution × conversion
A20: Pay per plan | B20: =trip_buyer_share*PerTrip!D14 -> 0.35387537 | C20: =(CAC!$B$7+Costs!$D$51) -> 7.8795554 | D20: =B20/C20 -> 0.044910575 | E20: One-year contribution × buyer share
A21: Group-trip commission | B21: =group_member_share*group_trips_member*GroupTrip!D15 -> 0.89482643 | C21: =(CAC!$B$7+Costs!$D$51) -> 7.8795554 | D21: =B21/C21 -> 0.11356306 | E21: One-year contribution × member share
A22: Affiliate | B22: =mau_per_signup*12*Affiliate!D15 -> -0.036084916 | C22: =(CAC!$B$7+Costs!$D$51) -> 7.8795554 | D22: =B22/C22 -> -0.0045795625 | E22: One-year contribution × active share
A23: Promoted experiences | B23: =mau_per_signup*12*Promoted!D12 -> 0.13791508 | C23: =(CAC!$B$7+Costs!$D$51) -> 7.8795554 | D23: =B23/C23 -> 0.017502902 | E23: One-year contribution × active share
A25: A ratio below 1 means each paid sign-up loses money in year one before fixed costs.

Sheet BreakEven
A1: Break-even and users needed for revenue targets
A2: Break-even covers fixed costs only (no founder salary). Revenue targets are net receipts per year, in steady state.
A4: Break-even volume per month
A5: Line | B5: Cheapest | C5: Default | D5: Premium
A6: Fixed cost per month (£) | B6: =Costs!C49 -> 15.143173 | C6: =Costs!D49 -> 24.953013 | D6: =Costs!E49 -> 83.05745
A7: Subscription: active paying users | B7: =IF(Subscription!C26>0,ROUNDUP(B6/Subscription!C26,0),"never") -> 9 | C7: =IF(Subscription!D26>0,ROUNDUP(C6/Subscription!D26,0),"never") -> 16 | D7: =IF(Subscription!E26>0,ROUNDUP(D6/Subscription!E26,0),"never") -> 35 | F7: "never" = contribution per unit is zero or negative
A8: Pay per plan: plans sold per month | B8: =IF(PerTrip!C11>0,ROUNDUP(B6/PerTrip!C11,0),"never") -> 9 | C8: =IF(PerTrip!D11>0,ROUNDUP(C6/PerTrip!D11,0),"never") -> 15 | D8: =IF(PerTrip!E11>0,ROUNDUP(D6/PerTrip!E11,0),"never") -> 32
A9: Group trips per month | B9: =IF(GroupTrip!C14>0,ROUNDUP(B6/GroupTrip!C14,0),"never") -> 2 | C9: =IF(GroupTrip!D14>0,ROUNDUP(C6/GroupTrip!D14,0),"never") -> 2 | D9: =IF(GroupTrip!E14>0,ROUNDUP(D6/GroupTrip!E14,0),"never") -> 6
A10: Affiliate: monthly active users | B10: =IF(Affiliate!C15>0,ROUNDUP(B6/Affiliate!C15,0),"never") -> 565 | C10: =IF(Affiliate!D15>0,ROUNDUP(C6/Affiliate!D15,0),"never") -> never | D10: =IF(Affiliate!E15>0,ROUNDUP(D6/Affiliate!E15,0),"never") -> never
A11: Promoted: monthly active users | B11: =IF(Promoted!C12>0,ROUNDUP(B6/Promoted!C12,0),"never") -> 179 | C11: =IF(Promoted!D12>0,ROUNDUP(C6/Promoted!D12,0),"never") -> 543 | D11: =IF(Promoted!E12>0,ROUNDUP(D6/Promoted!E12,0),"never") -> 8933
A13: Meta cost per sign-up incl. onboarding, Default (£) | B13: =CAC!B7+Costs!D51 -> 7.8795554
A14: Users needed per year for a revenue target (Default stack)
A15: Annual net revenue target | B15: 10000 | C15: 50000 | D15: 100000 | F15: Targets from the brief (edit to test others)
A16: Subscription
A17: New payers needed per year | B17: =B$15/Subscription!$D$24 -> 382.14563 | C17: =C$15/Subscription!$D$24 -> 1910.7281 | D17: =D$15/Subscription!$D$24 -> 3821.4563 | F17: Steady state: revenue a year = new payers a year × lifetime revenue per payer
A18: Sign-ups needed per year | B18: =B17/conv_paid -> 18197.411 | C18: =C17/conv_paid -> 90987.054 | D18: =D17/conv_paid -> 181974.11
A19: Active paying users at any time | B19: =B17*Subscription!$D$25/12 -> 475.48346 | C19: =C17*Subscription!$D$25/12 -> 2377.4173 | D19: =D17*Subscription!$D$25/12 -> 4754.8346
A20: Meta ad spend per year if all paid (£) | B20: =B18*$B$13 -> 143387.51 | C20: =C18*$B$13 -> 716937.53 | D20: =D18*$B$13 -> 1433875.1 | F20: Sign-ups × Meta cost per sign-up
A21: Founder hours per year if all organic | B21: =B18*post_hours/signups_post -> 1819.7411 | C21: =C18*post_hours/signups_post -> 9098.7054 | D21: =D18*post_hours/signups_post -> 18197.411 | F21: Budget is 7.5 h a week, 390 h a year, for everything
A22: Pay per plan
A23: Plans sold per year | B23: =B$15/PerTrip!$D$8 -> 5389.0837 | C23: =C$15/PerTrip!$D$8 -> 26945.419 | D23: =D$15/PerTrip!$D$8 -> 53890.837
A24: Buyers needed | B24: =B23/trips_per_buyer -> 1347.2709 | C24: =C23/trips_per_buyer -> 6736.3547 | D24: =D23/trips_per_buyer -> 13472.709
A25: Sign-ups needed per year | B25: =B24/trip_buyer_share -> 26945.419 | C25: =C24/trip_buyer_share -> 134727.09 | D25: =D24/trip_buyer_share -> 269454.19 | F25: Assumes buyers do not carry over to the next year
A26: Group-trip commission
A27: Group trips per year | B27: =B$15/GroupTrip!$D$19 -> 526.31579 | C27: =C$15/GroupTrip!$D$19 -> 2631.5789 | D27: =D$15/GroupTrip!$D$19 -> 5263.1579
A28: Attendees per year | B28: =B27*group_size -> 2631.5789 | C28: =C27*group_size -> 13157.895 | D28: =D27*group_size -> 26315.789
A29: Members needed | B29: =B28/group_trips_member -> 877.19298 | C29: =C28/group_trips_member -> 4385.9649 | D29: =D28/group_trips_member -> 8771.9298
A30: Sign-ups needed per year | B30: =B29/group_member_share -> 8771.9298 | C30: =C29/group_member_share -> 43859.649 | D30: =D29/group_member_share -> 87719.298
A31: Moderation hours per year | B31: =B27*group_mod_min/60 -> 263.15789 | C31: =C27*group_mod_min/60 -> 1315.7895 | D31: =D27*group_mod_min/60 -> 2631.5789
A32: Affiliate
A33: Plans per year | B33: =B$15/Affiliate!$D$10 -> 119047.62 | C33: =C$15/Affiliate!$D$10 -> 595238.1 | D33: =D$15/Affiliate!$D$10 -> 1190476.2
A34: Monthly active users needed | B34: =B33/(mau_plans*12) -> 19841.27 | C34: =C33/(mau_plans*12) -> 99206.349 | D34: =D33/(mau_plans*12) -> 198412.7
A35: Cumulative sign-ups needed | B35: =B34/mau_per_signup -> 79365.079 | C35: =C34/mau_per_signup -> 396825.4 | D35: =D34/mau_per_signup -> 793650.79
A36: Promoted experiences
A37: Monthly active users needed | B37: =B$15/Promoted!$D$10 -> 8333.3333 | C37: =C$15/Promoted!$D$10 -> 41666.667 | D37: =D$15/Promoted!$D$10 -> 83333.333 | F37: Brief check: £100k ≈ 83k MAU at £5 CPM
A38: Cumulative sign-ups needed | B38: =B37/mau_per_signup -> 33333.333 | C38: =C37/mau_per_signup -> 166666.67 | D38: =D37/mau_per_signup -> 333333.33
A39: VAT
A40: Must register for VAT? | B40: =IF(B$15>vat_threshold,"yes","no") -> no | C40: =IF(C$15>vat_threshold,"yes","no") -> no | D40: =IF(D$15>vat_threshold,"yes","no") -> yes | F40: Registered: VAT-inclusive Stripe prices lose 1/6 to HMRC (switch on Inputs)

Sheet Sensitivity
A1: Sensitivity: subscription, Meta channel
A2: Each row changes one input (blue) and links the rest (green). Formulas restate the Subscription, CAC and BreakEven logic.
A4: Scenario | B4: Monthly price (£) | C4: Annual price (£) | D4: Conversion | E4: Y1 retention monthly | F4: Y1 retention annual | G4: Meta CPC (£) | H4: Stars share | I4: Cost per payer-month (£) | J4: Acquisition cost per sign-up (£) | K4: Net per monthly payment (£) | L4: Net per annual payment (£) | M4: Blended LTV (£) | N4: CAC (£) | O4: LTV:CAC | P4: Sign-ups a year for £50k
A5: Base (Default stack) | B5: =price_month -> 4.99 | C5: =price_year -> 29.99 | D5: =conv_paid -> 0.021 | E5: =ret_monthly -> 0.1 | F5: =ret_annual -> 0.39 | G5: =meta_cpc -> 0.75 | H5: =Costs!D13 -> 1 | I5: =Costs!D41 -> 0.14025449 | J5: =Costs!D51 -> 0.37955543 | K5: =H5*B5*Costs!$D$22+(1-H5)*(B5/(1+vat_rate*vat_registered)-(B5*stripe_pct+stripe_fixed)) -> 3.096809 | L5: =H5*C5*Costs!$D$22+(1-H5)*(C5/(1+vat_rate*vat_registered)-(C5*stripe_pct+stripe_fixed)) -> 18.611884 | M5: =annual_share*(L5-12*I5)/(1-F5)+(1-annual_share)*(K5-I5)/(1-E5^(1/12)) -> 24.0739 | N5: =(G5/click_signup+J5)/D5 -> 375.21693 | O5: =M5/N5 -> 0.064159953 | P5: =50000/(annual_share*L5/(1-F5)+(1-annual_share)*K5/(1-E5^(1/12)))/D5 -> 90987.054
A6: Monthly price £2.99, annual £17.99 | B6: 2.99 | C6: 17.99 | D6: =conv_paid -> 0.021 | E6: =ret_monthly -> 0.1 | F6: =ret_annual -> 0.39 | G6: =meta_cpc -> 0.75 | H6: =Costs!D13 -> 1 | I6: =Costs!D41 -> 0.14025449 | J6: =Costs!D51 -> 0.37955543 | K6: =H6*B6*Costs!$D$22+(1-H6)*(B6/(1+vat_rate*vat_registered)-(B6*stripe_pct+stripe_fixed)) -> 1.855603 | L6: =H6*C6*Costs!$D$22+(1-H6)*(C6/(1+vat_rate*vat_registered)-(C6*stripe_pct+stripe_fixed)) -> 11.164648 | M6: =annual_share*(L6-12*I6)/(1-F6)+(1-annual_share)*(K6-I6)/(1-E6^(1/12)) -> 13.599167 | N6: =(G6/click_signup+J6)/D6 -> 375.21693 | O6: =M6/N6 -> 0.036243478 | P6: =50000/(annual_share*L6/(1-F6)+(1-annual_share)*K6/(1-E6^(1/12)))/D6 -> 151717.76
A7: Monthly price £9.99, annual £59.99 | B7: 9.99 | C7: 59.99 | D7: =conv_paid -> 0.021 | E7: =ret_monthly -> 0.1 | F7: =ret_annual -> 0.39 | G7: =meta_cpc -> 0.75 | H7: =Costs!D13 -> 1 | I7: =Costs!D41 -> 0.14025449 | J7: =Costs!D51 -> 0.37955543 | K7: =H7*B7*Costs!$D$22+(1-H7)*(B7/(1+vat_rate*vat_registered)-(B7*stripe_pct+stripe_fixed)) -> 6.1998241 | L7: =H7*C7*Costs!$D$22+(1-H7)*(C7/(1+vat_rate*vat_registered)-(C7*stripe_pct+stripe_fixed)) -> 37.229975 | M7: =annual_share*(L7-12*I7)/(1-F7)+(1-annual_share)*(K7-I7)/(1-E7^(1/12)) -> 50.260735 | N7: =(G7/click_signup+J7)/D7 -> 375.21693 | O7: =M7/N7 -> 0.13395114 | P7: =50000/(annual_share*L7/(1-F7)+(1-annual_share)*K7/(1-E7^(1/12)))/D7 -> 45477.191
A8: Conversion 1.0% | B8: =price_month -> 4.99 | C8: =price_year -> 29.99 | D8: 0.01 | E8: =ret_monthly -> 0.1 | F8: =ret_annual -> 0.39 | G8: =meta_cpc -> 0.75 | H8: =Costs!D13 -> 1 | I8: =Costs!D41 -> 0.14025449 | J8: =Costs!D51 -> 0.37955543 | K8: =H8*B8*Costs!$D$22+(1-H8)*(B8/(1+vat_rate*vat_registered)-(B8*stripe_pct+stripe_fixed)) -> 3.096809 | L8: =H8*C8*Costs!$D$22+(1-H8)*(C8/(1+vat_rate*vat_registered)-(C8*stripe_pct+stripe_fixed)) -> 18.611884 | M8: =annual_share*(L8-12*I8)/(1-F8)+(1-annual_share)*(K8-I8)/(1-E8^(1/12)) -> 24.0739 | N8: =(G8/click_signup+J8)/D8 -> 787.95554 | O8: =M8/N8 -> 0.030552359 | P8: =50000/(annual_share*L8/(1-F8)+(1-annual_share)*K8/(1-E8^(1/12)))/D8 -> 191072.81
A9: Conversion 10.7% (hard paywall) | B9: =price_month -> 4.99 | C9: =price_year -> 29.99 | D9: =conv_paywall -> 0.107 | E9: =ret_monthly -> 0.1 | F9: =ret_annual -> 0.39 | G9: =meta_cpc -> 0.75 | H9: =Costs!D13 -> 1 | I9: =Costs!D41 -> 0.14025449 | J9: =Costs!D51 -> 0.37955543 | K9: =H9*B9*Costs!$D$22+(1-H9)*(B9/(1+vat_rate*vat_registered)-(B9*stripe_pct+stripe_fixed)) -> 3.096809 | L9: =H9*C9*Costs!$D$22+(1-H9)*(C9/(1+vat_rate*vat_registered)-(C9*stripe_pct+stripe_fixed)) -> 18.611884 | M9: =annual_share*(L9-12*I9)/(1-F9)+(1-annual_share)*(K9-I9)/(1-E9^(1/12)) -> 24.0739 | N9: =(G9/click_signup+J9)/D9 -> 73.640705 | O9: =M9/N9 -> 0.32691024 | P9: =50000/(annual_share*L9/(1-F9)+(1-annual_share)*K9/(1-E9^(1/12)))/D9 -> 17857.272
A10: Monthly retention 6% | B10: =price_month -> 4.99 | C10: =price_year -> 29.99 | D10: =conv_paid -> 0.021 | E10: 0.06 | F10: =ret_annual -> 0.39 | G10: =meta_cpc -> 0.75 | H10: =Costs!D13 -> 1 | I10: =Costs!D41 -> 0.14025449 | J10: =Costs!D51 -> 0.37955543 | K10: =H10*B10*Costs!$D$22+(1-H10)*(B10/(1+vat_rate*vat_registered)-(B10*stripe_pct+stripe_fixed)) -> 3.096809 | L10: =H10*C10*Costs!$D$22+(1-H10)*(C10/(1+vat_rate*vat_registered)-(C10*stripe_pct+stripe_fixed)) -> 18.611884 | M10: =annual_share*(L10-12*I10)/(1-F10)+(1-annual_share)*(K10-I10)/(1-E10^(1/12)) -> 23.126262 | N10: =(G10/click_signup+J10)/D10 -> 375.21693 | O10: =M10/N10 -> 0.06163438 | P10: =50000/(annual_share*L10/(1-F10)+(1-annual_share)*K10/(1-E10^(1/12)))/D10 -> 94574.401
A11: Monthly retention 14% | B11: =price_month -> 4.99 | C11: =price_year -> 29.99 | D11: =conv_paid -> 0.021 | E11: 0.14 | F11: =ret_annual -> 0.39 | G11: =meta_cpc -> 0.75 | H11: =Costs!D13 -> 1 | I11: =Costs!D41 -> 0.14025449 | J11: =Costs!D51 -> 0.37955543 | K11: =H11*B11*Costs!$D$22+(1-H11)*(B11/(1+vat_rate*vat_registered)-(B11*stripe_pct+stripe_fixed)) -> 3.096809 | L11: =H11*C11*Costs!$D$22+(1-H11)*(C11/(1+vat_rate*vat_registered)-(C11*stripe_pct+stripe_fixed)) -> 18.611884 | M11: =annual_share*(L11-12*I11)/(1-F11)+(1-annual_share)*(K11-I11)/(1-E11^(1/12)) -> 24.968098 | N11: =(G11/click_signup+J11)/D11 -> 375.21693 | O11: =M11/N11 -> 0.066543103 | P11: =50000/(annual_share*L11/(1-F11)+(1-annual_share)*K11/(1-E11^(1/12)))/D11 -> 87842.942
A12: Meta CPC £0.45 | B12: =price_month -> 4.99 | C12: =price_year -> 29.99 | D12: =conv_paid -> 0.021 | E12: =ret_monthly -> 0.1 | F12: =ret_annual -> 0.39 | G12: 0.45 | H12: =Costs!D13 -> 1 | I12: =Costs!D41 -> 0.14025449 | J12: =Costs!D51 -> 0.37955543 | K12: =H12*B12*Costs!$D$22+(1-H12)*(B12/(1+vat_rate*vat_registered)-(B12*stripe_pct+stripe_fixed)) -> 3.096809 | L12: =H12*C12*Costs!$D$22+(1-H12)*(C12/(1+vat_rate*vat_registered)-(C12*stripe_pct+stripe_fixed)) -> 18.611884 | M12: =annual_share*(L12-12*I12)/(1-F12)+(1-annual_share)*(K12-I12)/(1-E12^(1/12)) -> 24.0739 | N12: =(G12/click_signup+J12)/D12 -> 232.35978 | O12: =M12/N12 -> 0.10360614 | P12: =50000/(annual_share*L12/(1-F12)+(1-annual_share)*K12/(1-E12^(1/12)))/D12 -> 90987.054
A13: Meta CPC £1.10 | B13: =price_month -> 4.99 | C13: =price_year -> 29.99 | D13: =conv_paid -> 0.021 | E13: =ret_monthly -> 0.1 | F13: =ret_annual -> 0.39 | G13: 1.1 | H13: =Costs!D13 -> 1 | I13: =Costs!D41 -> 0.14025449 | J13: =Costs!D51 -> 0.37955543 | K13: =H13*B13*Costs!$D$22+(1-H13)*(B13/(1+vat_rate*vat_registered)-(B13*stripe_pct+stripe_fixed)) -> 3.096809 | L13: =H13*C13*Costs!$D$22+(1-H13)*(C13/(1+vat_rate*vat_registered)-(C13*stripe_pct+stripe_fixed)) -> 18.611884 | M13: =annual_share*(L13-12*I13)/(1-F13)+(1-annual_share)*(K13-I13)/(1-E13^(1/12)) -> 24.0739 | N13: =(G13/click_signup+J13)/D13 -> 541.88359 | O13: =M13/N13 -> 0.044426332 | P13: =50000/(annual_share*L13/(1-F13)+(1-annual_share)*K13/(1-E13^(1/12)))/D13 -> 90987.054
A14: Cheapest stack costs | B14: =price_month -> 4.99 | C14: =price_year -> 29.99 | D14: =conv_paid -> 0.021 | E14: =ret_monthly -> 0.1 | F14: =ret_annual -> 0.39 | G14: =meta_cpc -> 0.75 | H14: =Costs!C13 -> 1 | I14: =Costs!C41 -> 0.03347815 | J14: =Costs!C51 -> 0.069413563 | K14: =H14*B14*Costs!$D$22+(1-H14)*(B14/(1+vat_rate*vat_registered)-(B14*stripe_pct+stripe_fixed)) -> 3.096809 | L14: =H14*C14*Costs!$D$22+(1-H14)*(C14/(1+vat_rate*vat_registered)-(C14*stripe_pct+stripe_fixed)) -> 18.611884 | M14: =annual_share*(L14-12*I14)/(1-F14)+(1-annual_share)*(K14-I14)/(1-E14^(1/12)) -> 25.668174 | N14: =(G14/click_signup+J14)/D14 -> 360.44826 | O14: =M14/N14 -> 0.071211811 | P14: =50000/(annual_share*L14/(1-F14)+(1-annual_share)*K14/(1-E14^(1/12)))/D14 -> 90987.054
A15: Premium stack costs | B15: =price_month -> 4.99 | C15: =price_year -> 29.99 | D15: =conv_paid -> 0.021 | E15: =ret_monthly -> 0.1 | F15: =ret_annual -> 0.39 | G15: =meta_cpc -> 0.75 | H15: =Costs!E13 -> 0 | I15: =Costs!E41 -> 0.31309276 | J15: =Costs!E51 -> 4.5641615 | K15: =H15*B15*Costs!$D$22+(1-H15)*(B15/(1+vat_rate*vat_registered)-(B15*stripe_pct+stripe_fixed)) -> 4.71515 | L15: =H15*C15*Costs!$D$22+(1-H15)*(C15/(1+vat_rate*vat_registered)-(C15*stripe_pct+stripe_fixed)) -> 29.34015 | M15: =annual_share*(L15-12*I15)/(1-F15)+(1-annual_share)*(K15-I15)/(1-E15^(1/12)) -> 36.252374 | N15: =(G15/click_signup+J15)/D15 -> 574.48388 | O15: =M15/N15 -> 0.06310425 | P15: =50000/(annual_share*L15/(1-F15)+(1-annual_share)*K15/(1-E15^(1/12)))/D15 -> 58175.376
A16: Web checkout (Stripe) instead of Stars | B16: =price_month -> 4.99 | C16: =price_year -> 29.99 | D16: =conv_paid -> 0.021 | E16: =ret_monthly -> 0.1 | F16: =ret_annual -> 0.39 | G16: =meta_cpc -> 0.75 | H16: 0 | I16: =Costs!D41 -> 0.14025449 | J16: =Costs!D51 -> 0.37955543 | K16: =H16*B16*Costs!$D$22+(1-H16)*(B16/(1+vat_rate*vat_registered)-(B16*stripe_pct+stripe_fixed)) -> 4.71515 | L16: =H16*C16*Costs!$D$22+(1-H16)*(C16/(1+vat_rate*vat_registered)-(C16*stripe_pct+stripe_fixed)) -> 29.34015 | M16: =annual_share*(L16-12*I16)/(1-F16)+(1-annual_share)*(K16-I16)/(1-E16^(1/12)) -> 38.833016 | N16: =(G16/click_signup+J16)/D16 -> 375.21693 | O16: =M16/N16 -> 0.10349484 | P16: =50000/(annual_share*L16/(1-F16)+(1-annual_share)*K16/(1-E16^(1/12)))/D16 -> 58175.376
A17: Upside: £9.99/£59.99, hard paywall, web checkout | B17: 9.99 | C17: 59.99 | D17: =conv_paywall -> 0.107 | E17: =ret_monthly -> 0.1 | F17: =ret_annual -> 0.39 | G17: =meta_cpc -> 0.75 | H17: 0 | I17: =Costs!D41 -> 0.14025449 | J17: =Costs!D51 -> 0.37955543 | K17: =H17*B17*Costs!$D$22+(1-H17)*(B17/(1+vat_rate*vat_registered)-(B17*stripe_pct+stripe_fixed)) -> 9.64015 | L17: =H17*C17*Costs!$D$22+(1-H17)*(C17/(1+vat_rate*vat_registered)-(C17*stripe_pct+stripe_fixed)) -> 58.89015 | M17: =annual_share*(L17-12*I17)/(1-F17)+(1-annual_share)*(K17-I17)/(1-E17^(1/12)) -> 80.39587 | N17: =(G17/click_signup+J17)/D17 -> 73.640705 | O17: =M17/N17 -> 1.0917314 | P17: =50000/(annual_share*L17/(1-F17)+(1-annual_share)*K17/(1-E17^(1/12)))/D17 -> 5664.8042
A18: Yellow = the changed input (blue if typed here, green if it links to another input or stack).
A20: Two-way: LTV:CAC (Default stack, Meta) by price level and conversion
A21: Price multiplier (× both prices) ↓ / conversion → | B21: 0.01 | C21: 0.021 | D21: 0.05 | E21: 0.107
A22: 0.6 | B22: =(annual_share*((Costs!$D$13*($A22*price_year)*Costs!$D$22+(1-Costs!$D$13)*(($A22*price_year)/(1+vat_rate*vat_registered)-(($A22*price_year)*stripe_pct+stripe_fixed)))-12*Costs!$D$41)/(1-ret_annual)+(1-annual_share)*((Costs!$D$13*($A22*price_month)*Costs!$D$22+(1-Costs!$D$13)*(($A22*price_month)/(1+vat_rate*vat_registered)-(($A22*price_month)*stripe_pct+stripe_fixed)))-Costs!$D$41)/(1-ret_monthly^(1/12)))/((meta_cpc/click_signup+Costs!$D$51)/B$21) -> 0.017268343 | C22: =(annual_share*((Costs!$D$13*($A22*price_year)*Costs!$D$22+(1-Costs!$D$13)*(($A22*price_year)/(1+vat_rate*vat_registered)-(($A22*price_year)*stripe_pct+stripe_fixed)))-12*Costs!$D$41)/(1-ret_annual)+(1-annual_share)*((Costs!$D$13*($A22*price_month)*Costs!$D$22+(1-Costs!$D$13)*(($A22*price_month)/(1+vat_rate*vat_registered)-(($A22*price_month)*stripe_pct+stripe_fixed)))-Costs!$D$41)/(1-ret_monthly^(1/12)))/((meta_cpc/click_signup+Costs!$D$51)/C$21) -> 0.03626352 | D22: =(annual_share*((Costs!$D$13*($A22*price_year)*Costs!$D$22+(1-Costs!$D$13)*(($A22*price_year)/(1+vat_rate*vat_registered)-(($A22*price_year)*stripe_pct+stripe_fixed)))-12*Costs!$D$41)/(1-ret_annual)+(1-annual_share)*((Costs!$D$13*($A22*price_month)*Costs!$D$22+(1-Costs!$D$13)*(($A22*price_month)/(1+vat_rate*vat_registered)-(($A22*price_month)*stripe_pct+stripe_fixed)))-Costs!$D$41)/(1-ret_monthly^(1/12)))/((meta_cpc/click_signup+Costs!$D$51)/D$21) -> 0.086341715 | E22: =(annual_share*((Costs!$D$13*($A22*price_year)*Costs!$D$22+(1-Costs!$D$13)*(($A22*price_year)/(1+vat_rate*vat_registered)-(($A22*price_year)*stripe_pct+stripe_fixed)))-12*Costs!$D$41)/(1-ret_annual)+(1-annual_share)*((Costs!$D$13*($A22*price_month)*Costs!$D$22+(1-Costs!$D$13)*(($A22*price_month)/(1+vat_rate*vat_registered)-(($A22*price_month)*stripe_pct+stripe_fixed)))-Costs!$D$41)/(1-ret_monthly^(1/12)))/((meta_cpc/click_signup+Costs!$D$51)/E$21) -> 0.18477127
A23: 1 | B23: =(annual_share*((Costs!$D$13*($A23*price_year)*Costs!$D$22+(1-Costs!$D$13)*(($A23*price_year)/(1+vat_rate*vat_registered)-(($A23*price_year)*stripe_pct+stripe_fixed)))-12*Costs!$D$41)/(1-ret_annual)+(1-annual_share)*((Costs!$D$13*($A23*price_month)*Costs!$D$22+(1-Costs!$D$13)*(($A23*price_month)/(1+vat_rate*vat_registered)-(($A23*price_month)*stripe_pct+stripe_fixed)))-Costs!$D$41)/(1-ret_monthly^(1/12)))/((meta_cpc/click_signup+Costs!$D$51)/B$21) -> 0.030552359 | C23: =(annual_share*((Costs!$D$13*($A23*price_year)*Costs!$D$22+(1-Costs!$D$13)*(($A23*price_year)/(1+vat_rate*vat_registered)-(($A23*price_year)*stripe_pct+stripe_fixed)))-12*Costs!$D$41)/(1-ret_annual)+(1-annual_share)*((Costs!$D$13*($A23*price_month)*Costs!$D$22+(1-Costs!$D$13)*(($A23*price_month)/(1+vat_rate*vat_registered)-(($A23*price_month)*stripe_pct+stripe_fixed)))-Costs!$D$41)/(1-ret_monthly^(1/12)))/((meta_cpc/click_signup+Costs!$D$51)/C$21) -> 0.064159953 | D23: =(annual_share*((Costs!$D$13*($A23*price_year)*Costs!$D$22+(1-Costs!$D$13)*(($A23*price_year)/(1+vat_rate*vat_registered)-(($A23*price_year)*stripe_pct+stripe_fixed)))-12*Costs!$D$41)/(1-ret_annual)+(1-annual_share)*((Costs!$D$13*($A23*price_month)*Costs!$D$22+(1-Costs!$D$13)*(($A23*price_month)/(1+vat_rate*vat_registered)-(($A23*price_month)*stripe_pct+stripe_fixed)))-Costs!$D$41)/(1-ret_monthly^(1/12)))/((meta_cpc/click_signup+Costs!$D$51)/D$21) -> 0.15276179 | E23: =(annual_share*((Costs!$D$13*($A23*price_year)*Costs!$D$22+(1-Costs!$D$13)*(($A23*price_year)/(1+vat_rate*vat_registered)-(($A23*price_year)*stripe_pct+stripe_fixed)))-12*Costs!$D$41)/(1-ret_annual)+(1-annual_share)*((Costs!$D$13*($A23*price_month)*Costs!$D$22+(1-Costs!$D$13)*(($A23*price_month)/(1+vat_rate*vat_registered)-(($A23*price_month)*stripe_pct+stripe_fixed)))-Costs!$D$41)/(1-ret_monthly^(1/12)))/((meta_cpc/click_signup+Costs!$D$51)/E$21) -> 0.32691024
A24: 1.5 | B24: =(annual_share*((Costs!$D$13*($A24*price_year)*Costs!$D$22+(1-Costs!$D$13)*(($A24*price_year)/(1+vat_rate*vat_registered)-(($A24*price_year)*stripe_pct+stripe_fixed)))-12*Costs!$D$41)/(1-ret_annual)+(1-annual_share)*((Costs!$D$13*($A24*price_month)*Costs!$D$22+(1-Costs!$D$13)*(($A24*price_month)/(1+vat_rate*vat_registered)-(($A24*price_month)*stripe_pct+stripe_fixed)))-Costs!$D$41)/(1-ret_monthly^(1/12)))/((meta_cpc/click_signup+Costs!$D$51)/B$21) -> 0.047157378 | C24: =(annual_share*((Costs!$D$13*($A24*price_year)*Costs!$D$22+(1-Costs!$D$13)*(($A24*price_year)/(1+vat_rate*vat_registered)-(($A24*price_year)*stripe_pct+stripe_fixed)))-12*Costs!$D$41)/(1-ret_annual)+(1-annual_share)*((Costs!$D$13*($A24*price_month)*Costs!$D$22+(1-Costs!$D$13)*(($A24*price_month)/(1+vat_rate*vat_registered)-(($A24*price_month)*stripe_pct+stripe_fixed)))-Costs!$D$41)/(1-ret_monthly^(1/12)))/((meta_cpc/click_signup+Costs!$D$51)/C$21) -> 0.099030495 | D24: =(annual_share*((Costs!$D$13*($A24*price_year)*Costs!$D$22+(1-Costs!$D$13)*(($A24*price_year)/(1+vat_rate*vat_registered)-(($A24*price_year)*stripe_pct+stripe_fixed)))-12*Costs!$D$41)/(1-ret_annual)+(1-annual_share)*((Costs!$D$13*($A24*price_month)*Costs!$D$22+(1-Costs!$D$13)*(($A24*price_month)/(1+vat_rate*vat_registered)-(($A24*price_month)*stripe_pct+stripe_fixed)))-Costs!$D$41)/(1-ret_monthly^(1/12)))/((meta_cpc/click_signup+Costs!$D$51)/D$21) -> 0.23578689 | E24: =(annual_share*((Costs!$D$13*($A24*price_year)*Costs!$D$22+(1-Costs!$D$13)*(($A24*price_year)/(1+vat_rate*vat_registered)-(($A24*price_year)*stripe_pct+stripe_fixed)))-12*Costs!$D$41)/(1-ret_annual)+(1-annual_share)*((Costs!$D$13*($A24*price_month)*Costs!$D$22+(1-Costs!$D$13)*(($A24*price_month)/(1+vat_rate*vat_registered)-(($A24*price_month)*stripe_pct+stripe_fixed)))-Costs!$D$41)/(1-ret_monthly^(1/12)))/((meta_cpc/click_signup+Costs!$D$51)/E$21) -> 0.50458395
A25: 2 | B25: =(annual_share*((Costs!$D$13*($A25*price_year)*Costs!$D$22+(1-Costs!$D$13)*(($A25*price_year)/(1+vat_rate*vat_registered)-(($A25*price_year)*stripe_pct+stripe_fixed)))-12*Costs!$D$41)/(1-ret_annual)+(1-annual_share)*((Costs!$D$13*($A25*price_month)*Costs!$D$22+(1-Costs!$D$13)*(($A25*price_month)/(1+vat_rate*vat_registered)-(($A25*price_month)*stripe_pct+stripe_fixed)))-Costs!$D$41)/(1-ret_monthly^(1/12)))/((meta_cpc/click_signup+Costs!$D$51)/B$21) -> 0.063762398 | C25: =(annual_share*((Costs!$D$13*($A25*price_year)*Costs!$D$22+(1-Costs!$D$13)*(($A25*price_year)/(1+vat_rate*vat_registered)-(($A25*price_year)*stripe_pct+stripe_fixed)))-12*Costs!$D$41)/(1-ret_annual)+(1-annual_share)*((Costs!$D$13*($A25*price_month)*Costs!$D$22+(1-Costs!$D$13)*(($A25*price_month)/(1+vat_rate*vat_registered)-(($A25*price_month)*stripe_pct+stripe_fixed)))-Costs!$D$41)/(1-ret_monthly^(1/12)))/((meta_cpc/click_signup+Costs!$D$51)/C$21) -> 0.13390104 | D25: =(annual_share*((Costs!$D$13*($A25*price_year)*Costs!$D$22+(1-Costs!$D$13)*(($A25*price_year)/(1+vat_rate*vat_registered)-(($A25*price_year)*stripe_pct+stripe_fixed)))-12*Costs!$D$41)/(1-ret_annual)+(1-annual_share)*((Costs!$D$13*($A25*price_month)*Costs!$D$22+(1-Costs!$D$13)*(($A25*price_month)/(1+vat_rate*vat_registered)-(($A25*price_month)*stripe_pct+stripe_fixed)))-Costs!$D$41)/(1-ret_monthly^(1/12)))/((meta_cpc/click_signup+Costs!$D$51)/D$21) -> 0.31881199 | E25: =(annual_share*((Costs!$D$13*($A25*price_year)*Costs!$D$22+(1-Costs!$D$13)*(($A25*price_year)/(1+vat_rate*vat_registered)-(($A25*price_year)*stripe_pct+stripe_fixed)))-12*Costs!$D$41)/(1-ret_annual)+(1-annual_share)*((Costs!$D$13*($A25*price_month)*Costs!$D$22+(1-Costs!$D$13)*(($A25*price_month)/(1+vat_rate*vat_registered)-(($A25*price_month)*stripe_pct+stripe_fixed)))-Costs!$D$41)/(1-ret_monthly^(1/12)))/((meta_cpc/click_signup+Costs!$D$51)/E$21) -> 0.68225766
A27: Cells at or above the LTV:CAC target (Inputs) are viable on paid acquisition.

Sheet FounderHours
A1: Founder hours per 100 users
